Workbook

Sheet PREGÃO ARP
A1: SEI | B1: MATERIAL/SERVIÇO | C1: Valor Ref Total | D1: N.º EDITAL | E1: N.º PREGÃO | F1: DATA ABERTURA SESSÃO | G1: STATUS | H1: Valor Final Total | I1: % VALOR REF X VALOR FINAL | AA1: STATUS PREGÃO
AA2: ANÁLISE PRELIMINAR UGE, VIA PASTA PÚBLICA
AA3: DEVOLVIDO AO REQUISITANTE P/ CORREÇÃO
AA4: DEVOLVIDO AO REQUISITANTE S/ CORREÇÃO
AA5: PEDIDO COFIN
AA6: ELABORAÇÃO EDITAL
AA7: ENVIADO À DF PARA PARECER
AA8: PUBLICADO PREGÃO
AA9: SESSÃO PÚBLICA
AA10: ANÁLISE DE HABILITAÇÃO DO PREGÃO
AA11: ELABORAÇÃO DE EMPENHO
AA12: HOMOLOGADO
AA13: ADQUIRIDO
... AA17: DESERTO
I22: =IFERROR(H22/C22," ")
I23: =IFERROR(H23/C23," ")
I24: =IFERROR(H24/C24," ")
I25: =IFERROR(H25/C25," ")
I26: =IFERROR(H26/C26," ")
I27: =IFERROR(H27/C27," ")
I28: =IFERROR(H28/C28," ")
I29: =IFERROR(H29/C29," ")
I30: =IFERROR(H30/C30," ")
I31: =IFERROR(H31/C31," ")
I32: =IFERROR(H32/C32," ")
I33: =IFERROR(H33/C33," ")
... I49: =IFERROR(H49/C49," ")

Sheet Dashboard
B1: Painel de Controle - ARP Viaturas
B3: Monitoramento de Consumo e Prazos

Sheet 12. RP CRETA
A1: PMESP-PRC | B1: PREGÃO | C1: NÚMERO DA ATA | D1: EMPRESA DETENTORA | E1: CNPJ | F1: DATA ASSINATURA ATA | G1: MATERIAL | H1: MARCA/MODELO | I1: VALOR UNITÁRIO | J1: QUANTIDADE DA ATA | K1: DATA VALIDADE | L1: CABE PRORROGAÇÃO
A2: 057.00075079/2025-15 | B2: 90008/2025 | C2: DL nº 023/13/25 CMM nº 00043/2025 | D2: HYUNDAI MOTOR BRASIL MONTADORA DE AUTOMÓVEIS | E2: 10.394.422/0001-42 | F2: 29/08/2025 | G2: RADIOPATRULHAMENTO | H2: Hyundai Creta | I2: 218500 | J2: 437 | K2: 46266 | L2: SIM
A5: Nº SEI DO ACIONAMENTO | B5: STATUS | C5: N.º NC | D5: N.º NL COTA | E5: PTRES | F5: VALOR NC | G5: TOTAL ACIONADO | H5: QTDADE ADITAMENTO | I5: QTDADE TOTAL ADITAMENTO | J5: VALOR CONTRATO / ADITAMENTO | K5: VALOR TOTAL ADITADO | L5: % DE ADITAMENTO | M5: ORIGEM DO RECURSO | N5: OPM BENEFICIADA | O5: N.º EMPENHO | P5: CONTRATO | Q5: ASSINATURA DO CONTRATO | R5: PRAZO DE ENTREGA | S5: PRORROGAÇÃO PRAZO DE ENTREGA | T5: NOVO PRAZO DE ENTREGA | U5: DATA DA ENTREGA | V5: PARLAMENTAR | W5: Nº EMENDA ou CONVÊNIO | X5: Nº DEMANDA | Y5: PROCESSO DEMANDA | Z5: Nº CONVÊNIO | AA5: CÓD. FONTE RECURSO | AB5: EIXO | AC5: TERMO DE ADESÃO | AD5: AÇÃO | AE5: GESTOR CONTRATO | AF5: VALOR TOTAL | AG5: OBSERVAÇÕES UGE | AH5: OBSERVAÇÕES GESTÃO CONTRATUAL
A6: 057.00075079/2025-15 (Vol. VII) | B6: PAGO | F6: 95484500 | G6: 437 | I6: 0 | J6: =G6*I2 -> 95484500 | K6: --- | L6: --- | M6: CONVÊNIO FEDERAL | O6: 2025NE00313 e 314 | P6: Contrato nº DL-064/13/25 | Q6: 45924 | R6: 40294 | S6: 20 DIAS | T6: 11074 | AE6: Ten Rebeca | AG6: PARCIALMENTE PENDENTE de liquidação/Pagamento (Inscrito em RPNP). Restam 399 Cretas a serem pagos pelo CMM referente as NE nº 2025NE00313, 2025NE00314. Os outros 38 Cretas serão pagos pelo 'transfere.gov' PELA DL. | AH6: pagamento de 149 unidades 057.00165196/2026-51
A7: 057.00075079/2025-15 (Vol. VIII) | B7: CONTRATO COM GESTOR CONTRATO | F7: 2840500 | G7: ---- | H7: 13 | I7: 13 | J7: =$I$2*H7 -> 2840500 | K7: =J6+J7 -> 98325000 | L7: =(K7/$J$6)-1 -> 0.029748284 | M7: CONVÊNIO FEDERAL | O7: 2025NE00427 e 428 | P7: 1º TERMO ADITIVO Nº DL – 022/13/25 | Q7: 45980 | R7: 43216 | S7: 60 DIAS | T7: 47325 | U7: 46226 | AE7: Ten Rebeca | AG7: PENDENTE de liquidação/Pagamento (Inscrito em RPNP), referente as NE nº 2025NE00427, 2025NE00428. | AH7: AGUARDANDO FOTOS
A8: 057.00075079/2025-15 (Vol VIII) | B8: CONTRATO COM GESTOR CONTRATO | F8: 218500 | G8: ---- | H8: 1 | I8: =I7+H8 -> 14 | J8: =$I$2*H8 -> 218500 | K8: =K7+J8 -> 98543500 | L8: =(K8/$J$6)-1 -> 0.032036613 | M8: TRANSFERÊNCIA ESPECIAL | N8: CPI 6 | O8: 2025NE00502 | P8: 2º TERMO ADITIVO Nº DL – 033/13/25 | Q8: 46030 | R8: 39259 | S8: 52 DIAS | T8: 47325 | U8: 46226 | AE8: Ten Rebeca | AG8: PENDENTE de liquidação/Pagamento (Inscrito em RPNP). Referente as NE nº 2025NE00502. | AH8: ENVIADO PARA UGE EM 31JUL26
A9: 057.00075079/2025-15 (Vol VIII) | B9: CONTRATO COM GESTOR CONTRATO | F9: 1748000 | G9: ---- | H9: 8 | I9: =I8+H9 -> 22 | J9: =$I$2*H9 -> 1748000 | K9: =K8+J9 -> 100291500 | L9: =(K9/$J$6)-1 -> 0.050343249 | M9: CONVÊNIO FEDERAL | O9: 2025NE00518 e 519 | P9: 3º TERMO ADITIVO Nº DL – 002/13/26 | Q9: 46051 | R9: 46930 | S9: 31 DIAS | T9: 47325 | U9: 46227 | AE9: Ten Rebeca | AG9: PENDENTE de liquidação/Pagamento (Inscrito em RPNP), referente as NE nº 2025NE00518, 2025NE00519. | AH9: AGUARDANDO FOTOS
A10: 057.00194661/2026-61 | B10: CONTRATO COM GESTOR CONTRATO | F10: 4370000 | G10: ---- | H10: 20 | I10: =I9+H10 -> 42 | J10: =$I$2*H10 -> 4370000 | K10: =K9+J10 -> 104661500 | L10: =(K10/$J$6)-1 -> 0.09610984 | M10: EXCECUÇÃO ORDINÁRIA | N10: CMM | O10: 2026NE00167 | P10: 4º TERMO ADITIVO CMM - 009/40.2/26 | Q10: 46135 | R10: 46285 | AE10: Ten Rebeca | AG10: PUBLICAÇÃO DO EMPENHO EM DOE 29ABR26 | AH10: 0BSERVAR A NOTA TÉCNICA: - 10 PARA O CPI4; - 07 PARA O CPI3 (MAIS ADESÃO DE 10 DO CPI3); - 03 PARA O CPM (MAIS ADESÃO DE 06) - CPI2 ADESÃO E AQUISIÇÃO DE 21 VTR
A11: 057.00282573/2026-15 | B11: CONTRATO COM GESTOR CONTRATO | C11: 2026NC18899 | D11: 2026NR00165 2026NR00166 | E11: 6.1811821e+15 | F11: 10706500 | G11: ---- | H11: 49 | I11: =I10+H11 -> 91 | J11: =$I$2*H11 -> 10706500 | K11: =K10+J11 -> 115368000 | L11: =(K11/$J$6)-1 -> 0.20823799 | M11: CONVÊNIO FEDERAL | N11: CMM | O11: 2026NE00482 2026NE00483 | P11: 5º TERMO ADITIVO CMM - 047/40.2/2026 | Q11: 46233 | R11: 46383 | Z11: 971465/2024 | AA11: 170050374 150010001 | AE11: Cap Monteiro | AG11: Processo restituido ao Gestor
G12: ---- | I12: =I11+H12 -> 91 | J12: =$I$2*H12 -> 0 | K12: =K11+J13 -> 115368000 | L12: =(K12/$J$6)-1 -> 0.20823799
G13: ---- | I13: =I12+H13 -> 91 | J13: =$I$2*H13 -> 0 | K13: =K12+J13 -> 115368000 | L13: =(K13/$J$6)-1 -> 0.20823799
G14: ---- | I14: =I13+H14 -> 91 | J14: =$I$2*H14 -> 0 | K14: =K13+J14 -> 115368000 | L14: =(K14/$J$6)-1 -> 0.20823799
G15: ---- | I15: =I14+H15 -> 91 | J15: =$I$2*H15 -> 0 | K15: =J14+J15 -> 0
G16: ---- | I16: =I15+H16 -> 91 | J16: =$I$2*H16 -> 0 | K16: =K15+J16 -> 0
G17: ---- | I17: =I16+H17 -> 91 | J17: =$I$2*H17 -> 0 | K17: =J16+J17 -> 0
G18: ---- | I18: =I17+H18 -> 91 | J18: =$I$2*H18 -> 0 | K18: =K17+J18 -> 0 | P18: =J2*2 -> 874
F19: TOTAL | G19: =SUM(G6:G18) -> 437 | H19: =SUM(H7:H18) -> 91 | J19: =$I$2*H19 -> 19883500 | K19: =J18+J19 -> 19883500
E25: =G6*0.25 -> 109.25

Sheet GERAL
A1: DATA | B1: =TODAY() -> 46258
A2: VIATURA | B2: VALOR UNITÁRIO | C2: QTDADE ATA | D2: QTDADE ACIONADA | E2: QTDADE REMANESCENTE | F2: QTDADE ADITADO | G2: POSSIBILIDADE DE ADITAMENTO | H2: DIAS RESTANTES ATÉ O VENCIMENTO | I2: VENCIMENTO
A3: RP CRETA | B3: ='12. RP CRETA'!I2 -> 218500 | C3: ='12. RP CRETA'!J2 -> 437 | D3: =IFS('12. RP CRETA'!G19 <= VALUE(C3), '12. RP CRETA'!G19, '12. RP CRETA'!G19 > VALUE(C3), VALUE(C3)) -> 437 | E3: =IFS(D3>=C3,"0",D3<C3,(C3-D3)) -> 0 | F3: ='12. RP CRETA'!H19 -> 91 | G3: =INT((D3*0.25)-F3) -> 18 | H3: =IFERROR(DATEDIF($B$1,I3,"D"), "VENCIDA") -> 8 | I3: ='12. RP CRETA'!K2 -> 46266
A4: SEDAN SIPOM | B4: ='3. SEDAN DESCARACTERIZA HB20'!K2 -> 115680 | C4: ='3. SEDAN DESCARACTERIZA HB20'!P2 -> 270 | D4: =SUM('3. SEDAN DESCARACTERIZA HB20'!G6:G30) -> 7 | E4: =IFS(D4>=C4,"0",D4<C4,(C4-D4)) -> 263 | F4: --- | G4: --- | H4: =IFERROR(DATEDIF($B$1,I4,"D"), "VENCIDA") -> 57 | I4: ='3. SEDAN DESCARACTERIZA HB20'!R2 -> 46315
A5: HATCH SIPOM | B5: ='2. HATCH DESCARACTERIZADA HB20'!I2 -> 111700 | C5: ='2. HATCH DESCARACTERIZADA HB20'!J2 -> 270 | D5: =SUM('2. HATCH DESCARACTERIZADA HB20'!G6:G30) -> 0 | E5: =IFS(D5>=C5,"0",D5<C5,(C5-D5)) -> 270 | F5: --- | G5: --- | H5: =IFERROR(DATEDIF($B$1,I5,"D"), "VENCIDA") -> 54 | I5: ='2. HATCH DESCARACTERIZADA HB20'!L2 -> 46312
A6: MOTO SIPOM | B6: ='4. MOTO SIPOM - KAWASAKIVERSYS '!I2 -> 35723.49 | C6: ='4. MOTO SIPOM - KAWASAKIVERSYS '!J2 -> 180 | D6: =SUM('4. MOTO SIPOM - KAWASAKIVERSYS '!G6:G38) -> 50 | E6: =IFS(D6>=C6,"0",D6<C6,(C6-D6)) -> 130 | F6: --- | G6: --- | H6: =IFERROR(DATEDIF($B$1,I6,"D"), "VENCIDA") -> 164 | I6: ='4. MOTO SIPOM - KAWASAKIVERSYS '!K2 -> 46422
A7: RURAL | B7: ='9. PICK-UP RURAL S-10'!I2 -> 258857.8 | C7: ='9. PICK-UP RURAL S-10'!J2 -> 150 | D7: =SUM('9. PICK-UP RURAL S-10'!G6:G130) -> 60 | E7: =IFS(D7>=C7,"0",D7<C7,(C7-D7)) -> 90 | F7: --- | G7: --- | H7: =IFERROR(DATEDIF($B$1,I7,"D"), "VENCIDA") -> 207 | I7: ='9. PICK-UP RURAL S-10'!Q2 -> 46465
A8: RP DUSTER | B8: ='5. RP DUSTER'!I2 -> 138044.95 | C8: ='5. RP DUSTER'!J2 -> 1300 | D8: ='5. RP DUSTER'!G400 -> 1256 | E8: =IFS(D8>=C8,"0",D8<C8,(C8-D8)) -> 44 | F8: --- | G8: --- | H8: =IFERROR(DATEDIF($B$1,I8,"D"), "VENCIDA") -> 207 | I8: ='5. RP DUSTER'!K2 -> 46465
A9: SUV CANIL | B9: ='14. SUV_CANIL - TRAILBLAZER 4X4'!I2 -> 311812.93 | C9: ='14. SUV_CANIL - TRAILBLAZER 4X4'!J2 -> 27 | D9: =SUM('14. SUV_CANIL - TRAILBLAZER 4X4'!F6:F18) -> 5 | E9: =IFS(D9>=C9,"0",D9<C9,(C9-D9)) -> 22 | F9: --- | G9: --- | H9: =IFERROR(DATEDIF($B$1,I9,"D"), "VENCIDA") -> 311 | I9: ='14. SUV_CANIL - TRAILBLAZER 4X4'!Q2 -> 46569
A10: RP TOYOTA | B10: ='RP TOYOTA'!I2 -> 201000 | C10: ='RP TOYOTA'!J2 -> 800 | D10: ='RP TOYOTA'!G13 -> 537 | E10: =IFS(D10>=C10,"0",D10<C10,(C10-D10)) -> 263 | F10: --- | G10: --- | H10: =IFERROR(DATEDIF($B$1,I10,"D"), "VENCIDA") -> VENCIDA | I10: ='RP TOYOTA'!L2 -> 45472
A11: MOTO RP | B11: ='7. RPM_ROCAM - SCRAMBLER 400X'!I2 -> 40580 | C11: ='7. RPM_ROCAM - SCRAMBLER 400X'!J2 -> 535 | D11: ='7. RPM_ROCAM - SCRAMBLER 400X'!G52 -> 535 | E11: =IFS(D11>=C11,"0",D11<C11,(C11-D11)) -> 0 | F11: ='7. RPM_ROCAM - SCRAMBLER 400X'!H52 -> 101 | G11: =INT((435*0.25)-F11) -> 7 | H11: =IFERROR(DATEDIF($B$1,I11,"D"), "VENCIDA") -> VENCIDA | I11: ='7. RPM_ROCAM - SCRAMBLER 400X'!O2 -> 46184
A12: BCM | B12: ='11. BCM FIAT DUCATO'!I2 -> 280500 | C12: ='11. BCM FIAT DUCATO'!J2 -> 19 | D12: =SUM('11. BCM FIAT DUCATO'!G6:G7) -> 15 | E12: =IFS(D12>=C12,"0",D12<C12,(C12-D12)) -> 4 | F12: --- | G12: --- | H12: =IFERROR(DATEDIF($B$1,I12,"D"), "VENCIDA") -> VENCIDA | I12: ='11. BCM FIAT DUCATO'!P2 -> 46156
A13: RE PCD | B13: ='8. RE PCD - FIAT SCUDO'!I2 -> R$ 289.800,00 | C13: ='8. RE PCD - FIAT SCUDO'!J2 -> 44 | D13: =SUM('8. RE PCD - FIAT SCUDO'!G6:G9) -> 5 | E13: =IFS(D13>=C13,"0",D13<C13,(C13-D13)) -> 39 | F13: --- | G13: --- | H13: =IFERROR(DATEDIF($B$1,I13,"D"), "VENCIDA") -> VENCIDA | I13: ='8. RE PCD - FIAT SCUDO'!Q2 -> 46149
A14: AMBULÂNCIA | B14: ='1. AMBULANCIA DUCATO'!I2 -> 299750 | C14: ='1. AMBULANCIA DUCATO'!J2 -> 33 | D14: =SUM('1. AMBULANCIA DUCATO'!G6:G8) -> 0 | E14: =IFS(D14>=C14,"0",D14<C14,(C14-D14)) -> 33 | F14: --- | G14: --- | H14: =IFERROR(DATEDIF($B$1,I14,"D"), "VENCIDA") -> VENCIDA | I14: ='1. AMBULANCIA DUCATO'!L2 -> 46162
A15: SUV FT BAEP | B15: ='6. FT_BAEP_TRAILBLAZER'!I2 -> 273700 | C15: ='6. FT_BAEP_TRAILBLAZER'!J2 -> 400 | D15: =SUM('6. FT_BAEP_TRAILBLAZER'!G6:G26) -> 160 | E15: =IFS(D15>=C15,"0",D15<C15,(C15-D15)) -> 240 | F15: --- | G15: --- | H15: =IFERROR(DATEDIF($B$1,I15,"D"), "VENCIDA") -> VENCIDA | I15: ='6. FT_BAEP_TRAILBLAZER'!K2 -> 46059
A16: SUV COE | B16: ='10. PICK-UP COE - HILUX 4X4'!I2 -> 339000 | C16: ='10. PICK-UP COE - HILUX 4X4'!J2 -> 15 | D16: =SUM('10. PICK-UP COE - HILUX 4X4'!G6:G13) -> 6 | E16: =IFS(D16>=C16,"0",D16<C16,(C16-D16)) -> 9 | F16: --- | G16: --- | H16: =IFERROR(DATEDIF($B$1,I16,"D"), "VENCIDA") -> VENCIDA | I16: ='10. PICK-UP COE - HILUX 4X4'!Q2 -> 46204
A17: SUV SIPOM | B17: ='13. SUV SIPOM DESCARACTERIZADA '!I2 -> R$ 110.989,00 | C17: ='13. SUV SIPOM DESCARACTERIZADA '!J2 -> 270 | D17: =SUM('13. SUV SIPOM DESCARACTERIZADA '!G6:G18) -> 3 | E17: =IFS(D17>=C17,"0",D17<C17,(C17-D17)) -> 267 | F17: --- | G17: --- | H17: =IFERROR(DATEDIF($B$1,I17,"D"), "VENCIDA") -> VENCIDA | I17: ='13. SUV SIPOM DESCARACTERIZADA '!Q2 -> 46160

Sheet 5. RP DUSTER
A1: 057.00196173/2026-98 | B1: PREGÃO | C1: NÚMERO DA ATA | D1: EMPRESA DETENTORA | E1: CNPJ | F1: DATA ASSINATURA ATA | G1: MATERIAL - SERVIÇO | H1: MARCA/MODELO | I1: VALOR UNITÁRIO | J1: QUANTIDADE DA ATA | K1: DATA VALIDADE | L1: CABE PRORROGAÇÃO | M1: GESTOR DA ATA
A2: 057.00394330/2024-67 | B2: 90047/2024 | C2: DL nº 005/11/25 CMM nº 00039/2024 | D2: NRTT SOLUÇÕES E SERVIÇOS LTDA | E2: 36.366.620/0001-96 | F2: 14/03/25 | G2: RADIOPATRULAHMENTO | H2: Renault Duster | I2: 138044.95 | J2: 1300 | K2: 46465 | L2: SIM | M2: Cap Monteiro
A5: Nº SEI DO ACIONAMENTO | B5: STATUS | C5: N.º NC | D5: N.º NR | E5: PTRES | F5: VALOR NC | G5: TOTAL ACIONADO | H5: ORIGEM DO RECURSO | I5: OPM BENEFICIADA | J5: N.º EMPENHO | K5: CONTRATO | L5: ASSINATURA DO CONTRATO | M5: PRAZO DE ENTREGA | N5: PRORROGAÇÃO PRAZO DE ENTREGA | O5: NOVO PRAZO DE ENTREGA | P5: DATA DA ENTREGA | Q5: PARLAMENTAR | R5: Nº EMENDA ou CONVÊNIO | S5: Nº DEMANDA | T5: PROCESSO DEMANDA | U5: Nº CONVÊNIO | V5: CÓD. FONTE RECURSO | W5: EIXO | X5: TERMO DE ADESÃO | Y5: AÇÃO | Z5: GESTOR CONTRATO | AA5: VALOR TOTAL | AB5: OBSERVAÇÕES UGE | AD5: OBSERVAÇÕES GESTÃO CONTRATUAL
A6: 057.00394330/2024-67 (Vol. VI) | B6: PAGO | G6: 365 | H6: CONVÊNIO FEDERAL | J6: 2025NE00285; 289; 299; | K6: Contrato nº DL-011/13/25 | L6: 45761 | M6: 45911 | N6: 10 DIAS | O6: 45921 | P6: VIDE OBSERVAÇÕES | Z6: Cap Maycon | AA6: 48325635 | AB6: Liquidado/Pago. 162 VTR pagas no Processso Principal (057.00394330/2024-67). 40 VTR pagas no Processo SEI nº 057.00511134/2025-44. 105 VTR pagas no Processo SEI nº 057.00449101/2025-78. 58 VTR pagas no Processo SEI nº 057.00466206/2025-91. | AD6: 28 VIATURAS ENTREGUES EM 08/08/26; 02 VIATURAS ENTREGUES EM 11/08/25; 24 VIATURAS ENTREGUES EM 12/08/25; 29 VIATURAS ENTREGUES EM 13/08/25; 11 VIATURAS ENTREGUES EM 14/08/25; 28 VIATURAS ENTREGUES EM 19/08/25; 23 VIATURAS ENTREGUES EM 21/08/25; 03 VIATURAS ENTREGUES EM 23/08/25; 25 VIATURAS ENTREGUES EM 27/08/25; 16 VIATURAS ENTREGUES EM 28/08/25; 13 VIATURAS ENTREGUES EM 29/08/25; 14 VIATURAS ENTREGUES EM 30/08/26; 21 VIATURAS ENTREGUES EM 01/09/25; 6 VIATURAS ENTREGUES EM 02/09/25; 25 VIATURAS ENTREGUES EM 03/09/25; 54 VIATURAS ENTREGUES EM 05/09/25; 18 VIATURAS ENTREGUES EM 08/09/25; 15 VIATURAS ENTREGUES EM 09/09/25; 10 VIATURAS ENTREGUES EM 24/09/25
A7: 057.00394330/2024-67 (Vol. VII) | B7: PAGO | E7: 180421 | G7: 2 | H7: EMENDA IMPOSITIVA | I7: CPI 3 | J7: 2025NE00126 E 127 | K7: Contrato nº DL-021/13/25 | L7: 45817 | M7: 45967 | N7: *** | O7: *** | P7: VIDE OBSERVAÇÕES | Q7: Marta Costa | R7: 202506765250 | V7: 150010001 | Z7: Cap Maycon | AA7: 264798 | AB7: Liquidado/Pago. Paga no SEI nº 057.00571529/2025-04 - OPM'S BENEFICIADAS: CPI-3 E M7 | AD7: 01 VIATURA ENTREGUE EM 29/10/25 E 01 VIATURA ENTREGUE EM 12/11/25
A8: 057.00394330/2024-67 (Vol. VIII) | B8: PAGO | E8: 180421 | G8: 1 | H8: EMENDA IMPOSITIVA | I8: CPAmb | J8: 2025NE00181 | K8: Contrato nº DL-039/13/25 | L8: 45870 | M8: 46020 | N8: *** | O8: *** | P8: 46034 | Q8: Beth Sahão | S8: 91663 | V8: 150010001 | Z8: Cap Maycon | AA8: 132399 | AB8: Liquidado/Pago. Paga no SEI nº 057.00043942/2026-56 | AD8: ***
A9: 057.00394330/2024-67 (Vol. VIII) | B9: PAGO | E9: 180430 | G9: 644 | H9: EXCECUÇÃO ORDINÁRIA | I9: OPMs | J9: 2025NE00188 | K9: Contrato nº DL-041/13/25 | L9: 45876 | M9: 46026 | N9: 11 DIAS | O9: 46038 | P9: VIDE OBSERVAÇÕES | V9: 275510001 | Z9: Cap Maycon | AA9: 85264956 | AB9: Liquidado/Pago. Todas as VTR pagas no processo SEI nº 057.00562307/2025-92 | AD9: 24 VIATURAS ENTREGUES EM 03/10/25; 27 VIATURAS ENTREGUES EM 06/10/25; 07 VIATURAS ENTREGUES EM 08/10/25; 18 VIATURAS ENTREGUES EM 10/10/25; 06 VIATURAS ENTREGUES EM 13/10/25; 04 VIATURAS ENTREGUES EM 14/10/25; 47 VIATURAS ENTREGUES EM 15/10/25; 26 VIATURAS ENTREGUES EM 16/10/25; 18 VIATURAS ENTREGUES EM 17/10/25; 05 VIATURAS ENTREGUES EM 21/10/25; 04 VIATURAS ENTREGUES EM 23/10/25; 09 VIATURAS ENTREGUES EM 24/10/25; 11 VIATURAS ENTREGUES EM 28/10/25; 02 VIATURAS ENTREGUES EM 29/10/25; 01 VIATURAS ENTREGUES EM 31/10/25; 08 VIATURAS ENTREGUES EM 05/11/25; 03 VIATURAS ENTREGUES EM 06/11/25; 10 VIATURAS ENTREGUES EM 07/11/25; 59 VIATURAS ENTREGUES EM 11/11/25; 17 VIATURAS ENTREGUES EM 12/11/25; 32 VIATURAS ENTREGUES EM 14/11/25; 08 VIATURAS ENTREGUES EM 17/11/25; 10 VIATURAS ENTREGUES EM 18/11/25; 21 VIATURAS ENTREGUES EM 19/11/25; 08 VIATURAS ENTREGUES EM 26/11/25; 09 VIATURAS ENTREGUES EM 04/12/25; 16 VIATURAS ENTREGUES EM 02/12/25; 38 VIATURAS ENTREGUES EM 09/12/25; 08 VIATURAS ENTREGUES EM 16/12/25; 01 VIATURAS ENTREGUES EM 27/01/26
A10: 057.00394330/2024-67 (Vol. IX) | B10: PAGO | E10: 180421 | G10: 1 | H10: EXCECUÇÃO ORDINÁRIA | I10: 14º BPM/I | J10: 2025NE00228 | K10: Contrato nº DL-044/13/25 | L10: 45882 | M10: 46032 | N10: *** | O10: *** | P10: 46034 | Q10: Rodrigo Moraes | S10: 91964 | V10: 150010001 | Z10: Cap Maycon | AA10: 132399 | AB10: Liquidado/Pago. Paga no SEI nº 057.00032745/2026-10 | AD10: ***
A11: 057.00394330/2024-67 (Vol. IX) | B11: PAGO | E11: 180421 | G11: 1 | H11: EXCECUÇÃO ORDINÁRIA | I11: CPA 12 | J11: 2025NE00229 | K11: Contrato nº DL-045/13/25 | L11: 45882 | M11: 46032 | N11: *** | O11: *** | P11: 46035 | Q11: André do Prado | R11: 2025010.71296 | S11: 91365 | V11: 150010001 | Z11: Cap Maycon | AA11: 132399 | AB11: Liquidado/Pago. Paga no SEI nº 057.00025235/2026-88 | AD11: ***
A12: 057.00394330/2024-67 (Vol. IX) | B12: PAGO | E12: 180430 | G12: 1 | H12: EXCECUÇÃO ORDINÁRIA | I12: CPI 2 | J12: 2025NE00239 | K12: Contrato nº DL-047/13/25 | L12: 45889 | M12: 46039 | N12: *** | O12: *** | P12: 46034 | R12: 2024.133.53355 | S12: 74979 | V12: 150010001 | Z12: Cap Maycon | AA12: 132399 | AB12: Liquidado/Pago. Paga no SEI nº 057.00020875/2026-00 - Dep. Luiz Philippe O. Bragança | AD12: ***
A13: 057.00394330/2024-67 (Vol. XII) | B13: PAGO | E13: 180430 | G13: 1 | H13: EXCECUÇÃO ORDINÁRIA | I13: 36º BPM/M | J13: 2025NE00297 | K13: Contrato nº DL-053/13/25 | L13: 45915 | M13: 46065 | N13: 10 DIAS | O13: 46075 | P13: 46076 | R13: 2025.331.74099 | S13: 94099 | V13: 275510001 | Z13: Cap Maycon | AA13: 132399 | AB13: Liquidado/Pago. Paga no SEI nº 057.00124419/2026-20. - Audiência Pública | AD13: ***
A14: 057.00394330/2024-67 (Vol. XIII) | B14: PAGO | E14: 180430 | G14: 1 | H14: EMENDA IMPOSITIVA | I14: 16º BPM/M | J14: 2025NE00275 | K14: Contrato nº DL-054/13/25 | L14: 45922 | M14: 46072 | N14: 10 DIAS | O14: 46082 | P14: 46076 | V14: 27066001 | Z14: Cap Maycon | AA14: 132399 | AB14: Liquidado/Pago. Paga no SEI nº 057.00126160/2026-51. -Dep. CEL Telhada | AD14: ***
A15: 057.00394330/2024-67 (Vol. XIII) | B15: PAGO | E15: 180430 | G15: 1 | H15: EXCECUÇÃO ORDINÁRIA | I15: 25º BPM/M | J15: 2025NE00302 | K15: Contrato nº DL-056/13/25 | L15: 45919 | M15: 46069 | N15: 10 DIAS | O15: 46079 | P15: 46076 | R15: 2025.331.74096 | S15: 94098 | V15: 150010001 | Z15: Cap Maycon | AA15: 132399 | AB15: Liquidado/Pago. Paga no SEI nº 057.00126160/2026-51. - Audiência Pública | AD15: ***
A16: 057.00394330/2024-67 (Vol. XV) | B16: PAGO | E16: 180430 | G16: 3 | H16: EMENDA IMPOSITIVA | I16: CPA 6 | J16: 2025NE00303 | K16: Contrato nº DL-058/13/25 | L16: 45924 | M16: 46074 | N16: 06 DIAS | O16: 46080 | P16: 46086 | Q16: Guto Zacarias | R16: 2023.275.51230 | S16: 94912 | V16: 275510001 | Z16: Cap Maycon | AA16: 397197 | AB16: No Ofício consta PENDENTE de liquidação/pagamento (Incrito em RPNP), referente a NE nº 2025NE00303. Porém consta o PAGAMENTO EM 14ABR26 NO SEI Nº 057.00086123/2026-01 | AD16: ***
A17: 057.00394330/2024-67 (Vol. XVI) | B17: PAGO | E17: 180430 | G17: 3 | H17: EMENDA IMPOSITIVA | I17: 55º BPM/I | J17: 2025NE00304 | K17: Contrato nº DL-059/13/25 | L17: 45924 | M17: 46074 | N17: 65 DIAS | O17: 46139 | P17: 46154 | Q17: Guto Zacarias | R17: 2023.275.51229 | S17: 94913 | V17: 275510001 | Z17: Ten Rebeca | AA17: 397197 | AB17: PENDENTE de liquidação/pagamento (Incrito em RPNP), referente a NE nº .2025NE00304 | AD17: ***
A18: 057.00394330/2024-67 (Vol. XVI) | B18: PAGO | E18: 180430 | G18: 1 | H18: EMENDA IMPOSITIVA | I18: CPI 6 | J18: 2025NE00305 | K18: Contrato nº DL-060/13/25 | L18: 45924 | M18: 46074 | N18: 65 DIAS | O18: 46139 | P18: 46154 | Q18: Solange Freitas | R18: 2023.287.51831 | S18: 94911 | V18: 275510001 | Z18: Ten Rebeca | AA18: 132399 | AB18: Liquidado/Pago NE nº 2025NE00305 - SEI 057.00249752/2026-41 | AD18: ***
A19: 057.00394330/2024-67 (Vol. XVII) | B19: PAGO | E19: 180430 | G19: 1 | H19: EXCECUÇÃO ORDINÁRIA | I19: 37º BPM/M | J19: 2025NE00306 | K19: Contrato nº DL-061/13/25 | L19: 45924 | M19: 46074 | N19: 65 DIAS | O19: 46139 | P19: 46153 | V19: 275510001 | Z19: Ten Rebeca | AA19: 132399 | AB19: Liquidado/Pago NE nº 2025NE00306. - SEI 057.00250266/2026-75 | AD19: ***
A20: 057.00394330/2024-67 (Vol. XVII) | B20: PAGO | E20: 180402 | G20: 2 | H20: FUNDO A FUNDO | I20: DSA/CG | J20: 2025NE00363 | K20: Contrato nº DL-074/13/25 | L20: 11621 | M20: 46111 | N20: *** | O20: *** | P20: 46146 | V20: 275930039 | Z20: Ten Rebeca | AA20: 264798 | AB20: Liquidado/Pago NE nº 2025NE00363.-SEI 057.00243427/2026-74 | AD20: ***
A21: 057.00394330/2024-67 (Vol. XVIII) | B21: CONTRATO COM GESTOR CONTRATO | E21: 180430 | G21: 1 | H21: TRANSFERÊNCIA VOLUNTÁRIA | J21: 2025NE00396 | K21: Contrato nº DL-083/13/25 | L21: 45961 | M21: 46144 | N21: 135 DIAS | O21: 46295 | Q21: Major Mecca | R21: 2024.059.62645 | S21: 81473 | V21: 275510001 | Z21: Ten Rebeca | AA21: 132399 | AB21: PENDENTE de liquidação/pagamento (Incrito em RPNP), referente a NE nº 2025NE00396. -Não foi localizada a entrega da VTR, ultima informação trata de um pedido de prorrogação para o dia 28MAI(057.00212949/2026-24).
A22: 057.00577787/2025-96 | B22: PAGO | G22: 7 | J22: 2025NE00446 | K22: Contrato nº DL-095/13/25 | L22: 38712 | M22: 38133 | N22: *** | O22: *** | P22: 46153 | Z22: Ten Rebeca | AA22: 926793 | AB22: PENDENTE de liquidação/pagamento (Incrito em RPNP), referente a NE nº 2025NE00446. Contrato se encontra no SEI nº 057.00577787/2025-96, o qual está RESTRITO. | AD22: ***
A23: 057.00593191/2025-33 | B23: CONTRATO COM GESTOR CONTRATO | E23: 180430 | G23: 1 | H23: TRANSFERÊNCIA ESPECIAL | J23: 2025NE00464 | K23: Contrato nº DL-103/13/25 | L23: 46010 | M23: 46160 | N23: 135 DIAS | O23: 11227 | R23: Dep Fed Bruno Garnem | V23: 170650014 | Z23: Ten Rebeca | AA23: 132399 | AB23: PENDENTE de liquidação/pagamento (Incrito em RPNP), referente a NE nº 2025NE00464. Não foi localizado maiores informações desta NE, somente o SEI 057.00593191/2025-33 para criação de prefixo
A24: 057.00594162/2025-99 | B24: CONTRATO COM GESTOR CONTRATO | E24: 180430 | G24: 1 | H24: TRANSFERÊNCIA ESPECIAL | J24: 2025NE00466 | K24: Contrato nº DL-105/13/25 | L24: 46010 | M24: 46160 | N24: 135 DIAS | O24: 11227 | R24: Dep Fed Kim Kataguiri | Z24: Ten Rebeca | AA24: 132399 | AB24: PENDENTE de liquidação/pagamento (Incrito em RPNP), referente a NE nº 2025NE00466. Não foi localizado maiores informações desta NE.
A25: 057.00626698/2025-81 | B25: CONTRATO COM GESTOR CONTRATO | E25: 180430 | G25: 14 | H25: TRANSFERÊNCIA ESPECIAL | J25: 2025NE00485 | K25: Contrato nº DL-119/13/25 | L25: 46024 | M25: 46174 | N25: 135 DIAS | O25: 11227 | R25: Dep Fed Paulo Freire Costa | Z25: Ten Rebeca | AA25: 1853586 | AB25: PENDENTE de liquidação/pagamento (Incrito em RPNP), referente a NE nº 2025NE00485. Contrato se encontra no SEI nº 057.00626698/2025-81, o qual está RESTRITO.
A26: 057.00628140/2025-30 | B26: CONTRATO COM GESTOR CONTRATO | E26: 180430 | G26: 1 | H26: TRANSFERÊNCIA ESPECIAL | J26: 2025NE00523 | K26: Contrato nº DL-120/13/25 | L26: 46038 | M26: 46188 | N26: 135 DIAS | O26: 11227 | R26: Dep Fed Paulo Teixeira | V26: 270660001 | Z26: Ten Rebeca | AA26: 132399 | AB26: PENDENTE de liquidação/pagamento (Incrito em RPNP)- Retornou ao St Aq. Frota dando prosseguimento a execução apos nova NE
A27: 057.00156849/2026-19 | B27: CANCELADO | C27: ------------------ | F27: ----------------------- | G27: ------------ | H27: FUNDO A FUNDO | I27: ---------------- | J27: ---------------- | K27: ---------------- | Q27: ----------------------- | R27: ----------------------- | S27: ----------------------- | T27: ----------------------- | U27: ---------------- | V27: ---------------- | W27: ---------------- | X27: ---------------- | Y27: ---------------- | Z27: ---------------- | AA27: ---------------- | AB27: A arp não foi passada pelo sistema compras.gov da DL para o CMM o que impossibilita o acionamento pelo CMM. ACIONADO MESMO ASSIM, CONFORME DETERMINAÇÃO DO DIRIGENTE. CONFORME PROCESSOS ABAIXO
A28: 057.00224400/2026-82 | B28: CONTRATO COM GESTOR CONTRATO | C28: 2026NC08460 | F28: R$ 27.974,65 | G28: 100 | H28: FUNDO A FUNDO | I28: CMM | J28: 2026NE00302 | K28: 011/40.2/26 | L28: 42547 | M28: 41604 | N28: *** | O28: *** | R28: FUNDESP | S28: ----------------------- | T28: ----------------------- | U28: ---------------- | W28: FISP | Z28: Ten Rebeca | AA28: =G28*$I$2 -> 13804495 | AB28: ENVIADO AO 2º CARTÓRIO EM 29/05/2026/ AGUARDANDO DISTRIUIÇÃO 4ª EM
A29: 057.00243291/2026-01 | B29: CONTRATO COM GESTOR CONTRATO | C29: 2026NC08459 | F29: R$ 248.115,25 | G29: 2 | I29: CMM | J29: 2026NE00303 e 2026NE00304 | K29: 010/40.2/26 | L29: 42547 | M29: 41604 | N29: *** | O29: *** | R29: FUNDESP | S29: ----------------------- | T29: ----------------------- | U29: ---------------- | W29: FISP | Z29: Ten Rebeca | AA29: =G29*$I$2 -> 276089.9 | AB29: ENVIADO AO GESTOR EM 18/06/2026/EM PRODUÇÃO
C30: 2026NC08461 | F30: R$ 13.804.495,00 | W30: FISP
A31: 057.00204080/2026-44 | B31: CONTRATO COM GESTOR CONTRATO | C31: 2026NC10023 | F31: 1490.15 | G31: 3 | H31: FUNDO A FUNDO | I31: CMM | J31: 2026NE00264 | K31: 007/40.2/26 | L31: 47264 | M31: 46321 | N31: *** | O31: *** | R31: FNSP | S31: ----------------------- | T31: ----------------------- | U31: ----------------------- | V31: 175950003 | W31: Plano Nacional de Segurança nas Escolas | X31: 50/21 | Y31: Fundo Nacional de Segurança Pública (FNSP) | Z31: Ten Rebeca | AA31: =G31*$I$2 -> 414134.85 | AB31: 2026NE00264 E 2026NE00265 - ELABORADOS EMPENHOS EM 22MAI26
B32: CONTRATO COM GESTOR CONTRATO | C32: 2026NC10023 | F32: 412644.7 | G32: 0 | I32: CMM | J32: 2026NE00265 | K32: 007/40.2/26 | L32: 47264 | M32: 46321 | N32: *** | O32: *** | R32: FNSP | S32: ----------------------- | T32: ----------------------- | U32: ----------------------- | V32: 275950003 | Z32: Ten Rebeca
A33: 057.00178984/2026-15 | B33: CONTRATO COM GESTOR CONTRATO | C33: 2026NC09276 | D33: 2026NR00082 | F33: 138044.95 | G33: 1 | H33: EMENDA IMPOSITIVA | I33: 6º BPM/I | J33: 2026NE00268 | K33: 006/40.2/26 | L33: 37068 | M33: 47417 | N33: *** | O33: *** | Q33: Major Mecca | R33: 202605977709 | S33: 101644 | T33: 20260370744 | V33: 150010001 | Z33: Ten Rebeca | AA33: =G33*$I$2 -> 138044.95
A34: 057.00236256/2026-27 | B34: CONTRATO COM GESTOR CONTRATO | C34: 2026NC09277 | D34: 2026NR00111 | F34: 138044.95 | G34: 1 | H34: EMENDA IMPOSITIVA | I34: CPI 3 | J34: 2026NE00308 | K34: 015/40.2/26 | L34: 45103 | M34: 44161 | N34: *** | O34: *** | Q34: Delegada Graciela | R34: 202603078320 | S34: 101669 | T34: 20260370753 | V34: 150010001 | Z34: Ten Rebeca | AA34: =G34*$I$2 -> 138044.95
A35: 057.00236305/2026-21 | B35: CONTRATO COM GESTOR CONTRATO | C35: 2026NC09278 | D35: 2026NR00109 | F35: 138044.95 | G35: 1 | H35: EMENDA IMPOSITIVA | I35: CPI 3 | J35: 2026NE00306 | K35: 018/40.2/26 | L35: 42181 | M35: 41239 | N35: *** | O35: *** | Q35: Delegada Graciela | R35: 202603078322 | S35: 101670 | T35: 20260370762 | V35: 150010001 | Z35: Ten Rebeca | AA35: =G35*$I$2 -> 138044.95
A36: 057.00236524/2026-19 | B36: CONTRATO COM GESTOR CONTRATO | C36: 2026NC09291 | D36: 2026NR00110 | F36: 276089.9 | G36: 2 | H36: EMENDA IMPOSITIVA | I36: 47º BPM/I | J36: 2026NE00307 | K36: 017/40.2/26 | L36: 43277 | M36: 42334 | N36: *** | O36: *** | Q36: Ricardo França | R36: 202626280080 | S36: 102382 | T36: 20260370904 | V36: 150010001 | Z36: Ten Rebeca | AA36: =G36*$I$2 -> 276089.9
A37: 057.00238504/2026-74 | B37: CONTRATO COM GESTOR CONTRATO | C37: 2026NC09295 | D37: 2026NR00113 | F37: 276089.9 | G37: 2 | H37: EMENDA IMPOSITIVA | I37: 26º BPM/I | J37: 2026NE00309 | K37: 013/40.2/26 | L37: 43277 | M37: 42334 | N37: *** | O37: *** | Q37: Gil Diniz Bolsonaro | R37: 202604682418 | S37: 102152 | T37: 20260370922 | V37: 150010001 | Z37: Ten Rebeca | AA37: =G37*$I$2 -> 276089.9
A38: 057.00238533/2026-36 | B38: CONTRATO COM GESTOR CONTRATO | C38: 2026NC09301 | D38: 2026NR00114 | F38: 138044.95 | G38: 1 | H38: EMENDA IMPOSITIVA | I38: 25º BPM/M | J38: 2026NE00312 | K38: 016/40.2/26 | L38: 43277 | M38: 42334 | N38: *** | O38: *** | Q38: Jorge Wilson Xerife do Consumidor | R38: 202605383428 | S38: 102292 | T38: 20260370978 | V38: 150010001 | Z38: Ten Rebeca | AA38: =G38*$I$2 -> 138044.95
A39: 057.00238557/2026-95 | B39: CONTRATO COM GESTOR CONTRATO | C39: 2026NC09300 | D39: 2026NR00115 | F39: 276089.9 | G39: 2 | H39: EMENDA IMPOSITIVA | I39: 25º BPM/M | J39: 2026NE00313 | K39: 014/40.2/26 | L39: 43277 | M39: 42334 | N39: *** | O39: *** | Q39: Profª Camila Godoi | R39: 202633280516 | S39: 102118 | T39: 20260371008 | V39: 150010001 | Z39: Ten Rebeca | AA39: =G39*$I$2 -> 276089.9
A40: 057.00226832/2026-28 | B40: CONTRATO COM GESTOR CONTRATO | C40: 2026NC13047 | D40: 2026NR00075 | E40: 180430 | F40: 2484809.1 | G40: 18 | H40: EXCECUÇÃO ORDINÁRIA | I40: CMM | J40: 2026NE00224 | K40: 005/40.2/26 | L40: 46153 | M40: 46303 | N40: *** | O40: *** | Q40: ----------------------- | R40: -------------------- | S40: -------------------- | T40: -------------------- | U40: -------------------- | V40: 150010001 | W40: -------------------- | X40: -------------------- | Y40: -------------------- | Z40: Ten Rebeca | AA40: 2484809.1
A41: 057.00267791/2026-20 | B41: CONTRATO COM GESTOR CONTRATO | C41: 2026NC14948 | D41: 2026NR00141 | E41: 180430 | F41: 138044.95 | G41: 1 | H41: TRANSFERÊNCIA VOLUNTÁRIA | I41: CPI-4 | J41: 2026NE00351 | K41: 024/40.2/26 | L41: 38924 | M41: 37981 | N41: *** | O41: *** | Q41: Capitão Telhada | R41: 202525675136 | S41: 98808 | T41: 20260421913 | U41: -------------------- | W41: -------------------- | X41: -------------------- | Y41: -------------------- | Z41: Ten Rebeca | AA41: =G41*I2 -> 138044.95 | AB41: Disponivel desde o dia 25/06 para assinatura da empresa.
A42: 057.00267801/2026-27 | B42: CONTRATO COM GESTOR CONTRATO | C42: 2026NC15246 | D42: 2026NR00150 | E42: 180430 | F42: 414134.85 | G42: 3 | H42: TRANSFERÊNCIA VOLUNTÁRIA | I42: CMM | J42: 2026NE00387 | K42: 023/40.2/26 | L42: 38924 | M42: 37981 | N42: *** | O42: *** | Q42: Leonardo Siqueira | R42: 202527775092 | S42: 98803 | T42: 20260418516 | U42: -------------------- | W42: -------------------- | X42: -------------------- | Y42: -------------------- | Z42: Ten Rebeca | AA42: =G42*$I$2 -> 414134.85 | AB42: Disponivel desde o dia 25/06 para assinatura da empresa.
...

Sheet 7. RPM_ROCAM - SCRAMBLER 400X
A1: PMESP-PRC | B1: PREGÃO | C1: NÚMERO DA ATA | D1: EMPRESA DETENTORA | E1: CNPJ | F1: DATA ASSINATURA ATA | G1: MATERIAL - SERVIÇO | H1: MARCA/MODELO | I1: VALOR UNITÁRIO | J1: QUANTIDADE DA ATA | K1: VALIDADE DA ATA | N1: ÓRGÃO GERENCIADOR | O1: DATA VALIDADE | P1: CABE PRORROGAÇÃO | Q1: GESTOR DA ATA | Y1: =I2*2 -> 81160
A2: 057.00214095/2025-30 | B2: 90032/2025 | C2: DL nº 018/13/25 CMM nº 00040/2025 | D2: TRIPLE T DISTRIBUIDORA DE VEÍCULOS LTDA | E2: 16.625.187/0001-59 | F2: 45849 | G2: Motocicleta abaixo de 500cc | H2: TRIUMPH/ SCRAMBLER 400X | I2: 40580 | J2: 535 | K2: 46214 | N2: CMM | O2: 46184 | P2: SIM | Q2: Cap Monteiro
Q3: NÃO SERÁ RENOVADO -EMPRESA NÃO QUER
A5: Nº SEI DO ACIONAMENTO | B5: STATUS | C5: N.º NC | D5: Nº NR | E5: PTRES | F5: VALOR NC | G5: TOTAL ACIONADO | H5: QTDADE ADITAMENTO | I5: QTDADE TOTAL ADITAMENTO | J5: VALOR CONTRATO / ADITAMENTO | K5: VALOR TOTAL ADITADO | L5: % DE ADITAMENTO | M5: ORIGEM DO RECURSO | N5: OPM BENEFICIADA | O5: N.º EMPENHO | P5: CONTRATO | Q5: ASSINATURA DO CONTRATO | R5: PRAZO DE ENTREGA | S5: PRORROGAÇÃO PRAZO DE ENTREGA | T5: NOVO PRAZO DE ENTREGA | U5: DATA DA ENTREGA | V5: PARLAMENTAR | W5: Nº EMENDA ou CONVÊNIO | X5: Nº DEMANDA | Y5: PROCESSO DEMANDA | Z5: Nº CONVÊNIO | AA5: CÓD. FONTE RECURSO | AB5: EIXO | AC5: TERMO DE ADESÃO | AD5: AÇÃO | AE5: GESTOR CONTRATO | AG5: OBSERVAÇÃO GESTÃO CONTRATUAL | AI5: OBSERVAÇÃO 2° CARTORIO
A6: 057.00214095/2025-30 (Vol. IV) | B6: PAGO | G6: 35 | I6: 0 | K6: 0 | L6: 0 | O6: 2025NE00170 | P6: Contrato DL nº 029/13/25 (Gestor Cap Maycon) | Q6: 44190 | R6: 45 DIAS | S6: 38043 | T6: 7 DIAS | U6: 46058 | V6: 40600 | AE6: Cap Maycon
A7: 057.00214095/2025-30 (Vol. V) | B7: PAGO | E7: 4.1275125e+15 | G7: 3 | I7: 0 | K7: 0 | L7: 0 | M7: EMENDA IMPOSITIVA | N7: 30º BPM/M | O7: 2025NE00249 | P7: Contrato DL nº 048/13/25 (Gestor Cap Maycon) | Q7: 44587 | R7: 15 DIAS | S7: 39139 | T7: *** | U7: 46058 | V7: *** | W7: 202502566474 | AA7: 150010001 | AE7: Cap Maycon
A8: 057.00214095/2025-30 (Vol. IV) | B8: PAGO | E8: 4.1275125e+15 | G8: 2 | I8: 0 | K8: 0 | L8: 0 | M8: EMENDA IMPOSITIVA | N8: 26º BPM/I | O8: 2025NE00247 | P8: Contrato DL nº 049/13/25 (Gestor Cap Maycon) | Q8: 44587 | R8: 15 DIAS | S8: 39139 | T8: *** | U8: 46058 | V8: *** | W8: 202500765267 | AA8: 150010001 | AE8: Cap Maycon
A9: 057.00214095/2025-30 (Vol. VI) | B9: PAGO | E9: 6.1811821e+15 | G9: 3 | I9: 0 | K9: 0 | L9: 0 | N9: 7º BPM/I | O9: 2025NE00319 | P9: Contrato DL nº 066/13/25 | Q9: 46809 | R9: 30 DIAS | S9: *** | T9: 40 DIAS | U9: 46120 | V9: 40294 | X9: 82477 | AA9: 275510001 | AE9: Ten Rebeca
A10: 057.00214095/2025-30 (Vol. V) | B10: PAGO | G10: 1 | I10: 0 | K10: 0 | L10: 0 | O10: 2025NE00318 | P10: Contrato DL nº 067/13/25 | Q10: 46809 | R10: 30 DIAS | S10: *** | T10: 40 DIAS | U10: 46120 | V10: 40294 | AE10: Ten Rebeca
A11: 057.00214095/2025-30 (Vol. VI) | B11: PAGO | E11: 6.1811821e+15 | G11: 2 | I11: 0 | K11: 0 | L11: 0 | N11: CPA 6 | O11: 2025NE00423 | P11: Contrato DL nº 082/13/25 | Q11: 37767 | R11: *** | S11: *** | T11: *** | U11: 46120 | V11: *** | AA11: 150010001 | AE11: Ten Rebeca
A12: 057.00593423/2025-53 | B12: PAGO | G12: 1 | I12: 0 | K12: 0 | L12: 0 | M12: TRANSFERÊNCIA ESPECIAL | N12: CPA 6 | O12: 2025NE00465 | P12: Contrato DL nº 104/13/25 | Q12: 43246 | R12: *** | S12: *** | T12: *** | U12: 46120 | V12: *** | AA12: 170650014 | AE12: Ten Rebeca
A13: 057.00625958/2025-09 | B13: CONTRATO COM GESTOR CONTRATO | E13: 6.1811821e+15 | G13: 19 | I13: 0 | K13: 0 | L13: 0 | M13: TRANSFERÊNCIA ESPECIAL | N13: CPI 6 | O13: 2025NE00483 | P13: Contrato DL nº 117/13/25 | Q13: 39259 | R13: 15 DIAS | S13: 44738 | T13: *** | U13: 46184 | V13: *** | AA13: 170650014 | AE13: Ten Rebeca
A14: 057.00627853/2025-86 | B14: CONTRATO COM GESTOR CONTRATO | E14: 6.1811821e+15 | G14: 17 | I14: 0 | K14: 0 | L14: 0 | M14: TRANSFERÊNCIA ESPECIAL | O14: 2025NE00484 | P14: Contrato DL nº 118/13/25 | Q14: 37068 | R14: 15 DIAS | S14: 42547 | T14: *** | U14: 46184 | V14: *** | AA14: 170650014 | AE14: Ten Rebeca
A15: 057.00640682/2025-81 | B15: CONTRATO COM GESTOR CONTRATO | E15: 4.1275125e+15 | G15: 2 | I15: 0 | K15: 0 | L15: 0 | M15: EMENDA IMPOSITIVA | N15: 3º BPM/M | O15: 2025NE00510 | P15: Contrato DL nº 132/13/25 | Q15: 47264 | R15: 15 DIAS | S15: 41451 | T15: *** | U15: 46184 | V15: *** | AA15: 150010001 | AE15: Ten Rebeca
A16: 057.00640719/2025-71 | B16: PAGO | E16: 4.1275125e+15 | G16: 1 | I16: 0 | K16: 0 | L16: 0 | M16: EMENDA IMPOSITIVA | N16: 46º BPM/M | O16: 2025NE00511 | P16: Contrato DL nº 133/13/25 | Q16: 47264 | R16: 15 DIAS | S16: 41451 | T16: *** | U16: 46184 | V16: *** | AA16: 150010001 | AE16: Ten Rebeca
A17: 057.00256176/2026-98 | B17: CONTRATO COM GESTOR CONTRATO | C17: 2026NC09282 | D17: 2026NR00162 | E17: 180421 | G17: 2 | I17: 0 | K17: 0 | L17: 0 | M17: EMENDA IMPOSITIVA | N17: 12º BPM/M | O17: 2026NE00410 | P17: 025/40.2/26 | Q17: 11135 | R17: 46717 | S17: *** | T17: *** | V17: Tomé Abduch | W17: 202628878766 | X17: 101981 | Y17: 20260370815 | Z17: ------------ | AB17: ------------ | AC17: ------------ | AD17: ------------ | AE17: Ten Rebeca
A18: 057.00256305/2026-48 | B18: CONTRATO COM GESTOR CONTRATO | C18: 2026NC09283 | D18: 2026NR00161 | E18: 180421 | G18: 6 | I18: 0 | K18: 0 | L18: 0 | M18: EMENDA IMPOSITIVA | N18: 12º BPM/M | O18: 2026NE00406 | P18: 026/40.2/26 | Q18: 11135 | R18: 46717 | S18: *** | T18: *** | V18: Fábio Faria de Sá | W18: 202632479641 | X18: 102101 | Y18: 20260370842 | Z18: ------------ | AB18: ------------ | AC18: ------------ | AD18: ------------ | AE18: Ten Rebeca | AG18: 2026NR00152 | AH18: 2026NR00163 = 243.480,00
A19: 057.00256309/2026-26 | B19: CONTRATO COM GESTOR CONTRATO | C19: 2026NC09284 | D19: 2026NR00168 | E19: 180421 | G19: 3 | I19: 0 | K19: 0 | L19: 0 | M19: EMENDA IMPOSITIVA | N19: 3º BPM/M | O19: 2026NE00426 | P19: 027/40.2/26 | Q19: 37828 | R19: 11288 | S19: *** | T19: *** | V19: Fábio Faria de Sá | W19: 202632479643 | X19: 102103 | Y19: 20260370861 | Z19: ------------ | AB19: ------------ | AC19: ------------ | AD19: ------------ | AE19: Ten Rebeca
A20: 057.00256314/2026-39 | B20: CONTRATO COM GESTOR CONTRATO | C20: 2026NC09288 | D20: 2026NR00164 | E20: 180421 | G20: 2 | I20: 0 | K20: 0 | L20: 0 | M20: EMENDA IMPOSITIVA | N20: 22º BPM/M | O20: 2026NE00412 | P20: 028/40.2/26 | Q20: 37828 | R20: 11288 | S20: *** | T20: *** | V20: Fábio Faria de Sá | W20: 202632479673 | X20: 102104 | Y20: 20260370898 | Z20: ------------ | AB20: ------------ | AC20: ------------ | AD20: ------------ | AE20: Ten Rebeca
A21: 057.00256344/2026-45 | B21: CONTRATO COM GESTOR CONTRATO | C21: 2026NC09327 | D21: 2026NR00188 | E21: 180421 | G21: 1 | I21: 0 | K21: 0 | L21: 0 | M21: EMENDA IMPOSITIVA | N21: 25º BPM/M | O21: 2026NE00442 | P21: 042/40.2/26 | Q21: 46226 | R21: 46376 | S21: *** | T21: *** | V21: Reis | W21: 202628478047 | X21: 101667 | Y21: 20260118556 | Z21: ------------ | AB21: ------------ | AC21: ------------ | AD21: ------------ | AE21: Ten Rebeca | AG21: tem que ver | AH21: 2026NR00160 PTR RURAL S-10
A22: 057.00249709/2026-85 | B22: CONTRATO COM GESTOR CONTRATO | C22: 2026NC14964 | D22: 2026NR00106 | G22: 435 | I22: 0 | J22: =G22*$I$2 -> 17652300 | K22: =J22 -> 17652300 | L22: 0 | M22: EXCECUÇÃO ORDINÁRIA | N22: CMM | O22: 2026NE00290 | P22: CONTRATO nº CMM-08/40.2/26 | Q22: 46899 | R22: 45956 | S22: *** | T22: *** | W22: -------- | X22: -------- | Y22: -------- | Z22: -------- | AA22: 150010001 | AB22: -------- | AC22: -------- | AD22: -------- | AE22: Ten Rebeca
A23: 057.00249709/2026-85 | B23: CONTRATO COM GESTOR CONTRATO | C23: 2026NC14964 | D23: 2026NR00106 | G23: ---- | H23: 15 | I23: =I22+H23 -> 15 | J23: =I23*$I$2 -> 608700 | K23: =K22+J23 -> 18261000 | L23: =J23/$J$22 -> 0.034482759 | M23: EXCECUÇÃO ORDINÁRIA | N23: CMM | O23: 2026NE00341 | P23: 1º TERMO ADITIVO nº 014/40.21/26 | Q23: 42912 | R23: 41969 | S23: *** | T23: *** | W23: -------- | X23: -------- | Y23: -------- | Z23: -------- | AA23: 150010001 | AB23: -------- | AC23: -------- | AD23: --------
A24: 057.00268115/2026-73 | B24: CONTRATO COM GESTOR CONTRATO | C24: 2026NC14942 | D24: 2026NR00139 | E24: 180430 | F24: 81160 | G24: ---- | H24: 2 | I24: =I23+H24 -> 17 | J24: =H24*$I$2 -> 81160 | K24: =K23+J24 -> 18342160 | L24: =L23+(J24/$J$22) -> 0.03908046 | M24: TRANSFERÊNCIA VOLUNTÁRIA | N24: 17º BPM/M | O24: 2026NE00349 | P24: 2º TERMO ADITIVO nº 028/40.2/26 | Q24: 45133 | R24: 44191 | S24: *** | T24: *** | V24: Capitão Telhada | W24: 202525672095 | X24: 95491 | Y24: 20260418456 | Z24: ------------ | AB24: ------------ | AC24: ------------ | AD24: ------------ | AE24: =H24*$I$2 -> 81160
A25: 057.00268116/2026-18 | B25: CONTRATO COM GESTOR CONTRATO | C25: 2026NC15224 | D25: 2026NR00152 | E25: 180430 | F25: 284060 | G25: ---- | H25: 7 | I25: =I24+H25 -> 24 | J25: =H25*$I$2 -> 284060 | K25: =K24+J25 -> 18626220 | L25: =L24+(J25/$J$22) -> 0.055172414 | M25: TRANSFERÊNCIA VOLUNTÁRIA | N25: 7º BPM/I | O25: 2026NE00389 | P25: 3º TERMO ADITIVO nº 029/40.2/26 | Q25: 45133 | R25: 44191 | S25: *** | T25: *** | V25: Maria Lúcia Amary | W25: 202506569641 | X25: 91734 | Y25: 20260424491 | AE25: =H25*$I$2 -> 284060 | AG25: 2026nr00152 correto
A26: 057.00268119/2026-51 | B26: CONTRATO COM GESTOR CONTRATO | C26: 2026NC15237 | D26: 2026NR00153 | E26: 180430 | F26: 162320 | G26: ---- | H26: 4 | I26: =I25+H26 -> 28 | J26: =H26*$I$2 -> 162320 | K26: =K25+J26 -> 18788540 | L26: =L25+(J26/$J$22) -> 0.064367816 | M26: TRANSFERÊNCIA VOLUNTÁRIA | N26: 7º BPM/I | O26: 2026NE00390 | P26: 4º TERMO ADITIVO nº 030/40.2/26 | Q26: 45133 | R26: 44191 | S26: *** | T26: *** | V26: Vitão do Cachorrão | W26: 202528971562 | X26: 93375 | Y26: 20260418425 | AE26: =H26*$I$2 -> 162320
A27: 057.00268122/2026-75 | B27: CONTRATO COM GESTOR CONTRATO | C27: 2026NC15239 | D27: 2026NR00154 | E27: 180430 | F27: 162320 | G27: ---- | H27: 4 | I27: =I26+H27 -> 32 | J27: =H27*$I$2 -> 162320 | K27: =K26+J27 -> 18950860 | L27: =L26+(J27/$J$22) -> 0.073563218 | M27: TRANSFERÊNCIA VOLUNTÁRIA | N27: 23º BPM/I | O27: 2026NE00391 | P27: 5º TERMO ADITIVO nº 031/40.2/26 | Q27: 45133 | R27: 44191 | S27: *** | T27: *** | V27: Major Mecca | W27: 202505975406 | X27: 96747 | Y27: 20260418479
A28: 057.00268126/2026-53 | B28: CONTRATO COM GESTOR CONTRATO | C28: 2026NC15253 | D28: 2026NR00179 | F28: 340017.8 | G28: ---- | H28: 2 | I28: =I27+H28 -> 34 | J28: =H28*$I$2 -> 81160 | K28: =K27+J28 -> 19032020 | L28: =L27+(J28/$J$22) -> 0.07816092 | M28: TRANSFERÊNCIA VOLUNTÁRIA | N28: 31º BPM/I | O28: 2026NE00430 | P28: 6º TERMO ADITIVO nº 032/40.2/26 | Q28: 46960 | R28: 46017 | S28: *** | T28: *** | V28: Capitão Telhada | W28: 202525675146 | X28: 98807 | Y28: 20260421941 | Z28: -------------------- | AB28: -------------------- | AC28: -------------------- | AD28: -------------------- | AE28: =I2*H28 -> 81160
A29: 057.00272043/2026-69 | B29: CONTRATO COM GESTOR CONTRATO | C29: 2026NC15246 | D29: 2026NR00178 | E29: 180430 | F29: 495294.85 | G29: ---- | H29: 2 | I29: =I28+H29 -> 36 | J29: =H29*$I$2 -> 81160 | K29: =K28+J29 -> 19113180 | L29: =L28+(J29/$J$22) -> 0.082758621 | M29: TRANSFERÊNCIA VOLUNTÁRIA | N29: CMM | O29: 2026NE00429 | P29: 7º TERMO ADITIVO nº CMM-33/40.2/26 | Q29: 46248 | R29: 46398 | S29: *** | T29: *** | V29: Leonardo Siqueira | W29: 202527775092 | X29: 98803 | Y29: 20260418516
A30: 057.00308666/2026-87 | B30: CONTRATO COM GESTOR CONTRATO | C30: 2026NC19433 | D30: 2026NR00174 | E30: 180430 | F30: 81160 | G30: ---- | H30: 2 | I30: =I29+H30 -> 38 | J30: =H30*$I$2 -> 81160 | K30: =K29+J30 -> 19194340 | L30: =L29+(J30/$J$22) -> 0.087356322 | M30: TRANSFERÊNCIA VOLUNTÁRIA | N30: 46º BPM/I | O30: 2026NE00456 | P30: 8º TERMO ADITIVO nº CMM-34/40.2/26 | Q30: 46246 | R30: 46396 | S30: *** | T30: *** | V30: Major Mecca | W30: 202605985127 | X30: 107499 | Y30: 20260435366
A31: 057.00267946/2026-28 | B31: CONTRATO COM GESTOR CONTRATO | C31: 2026NC15212 | D31: 2026NR00151 2026NR00176 | F31: 2565969.1 | G31: ---- | H31: 2 | I31: =I30+H31 -> 40 | J31: =H31*$I$2 -> 81160 | K31: =K30+J31 -> 19275500 | L31: =L30+(J31/$J$22) -> 0.091954023 | M31: TRANSFERÊNCIA VOLUNTÁRIA | N31: PMESP | O31: 2026NE00427 | P31: 9 º TERMO ADITIVO nº CMM-35/40.2/26 | Q31: 46246 | R31: 46396 | S31: *** | T31: *** | V31: Tomé Abduch | W31: 202528869552 | X31: 91735 | Y31: 20260418267 | AE31: =H31*$I$2 -> 81160
A32: 057.00357157/2026-88 | B32: CONTRATO COM GESTOR CONTRATO | C32: 2026NC19428 | D32: 2026NR00230 | E32: saiu 365.220,00 | F32: 486960 | G32: ---- | H32: 3 | I32: =I31+H32 -> 43 | J32: =H32*$I$2 -> 121740 | K32: =K31+J32 -> 19397240 | L32: =L31+(J32/$J$22) -> 0.098850575 | M32: TRANSFERÊNCIA VOLUNTÁRIA | N32: 12º BPM/M | O32: 2026NE00508 | P32: 10º TERMO ADITIVO nº CMM-36/40.2/26 | Q32: 46251 | R32: 46401 | S32: *** | T32: *** | V32: Guto Zacarias | W32: 202527586048 | X32: 117326 | Y32: 20260418533 | AI32: Falta Publicar PNCP DOE SAI DIA 19/08
A33: 057.00357167/2026-13 | B33: CONTRATO COM GESTOR CONTRATO | C33: 2026NC19430 | D33: 2026NR00224 | E33: Saiu 365.220,00 | F33: 486960 | G33: ---- | H33: 3 | I33: =I32+H33 -> 46 | J33: =H33*$I$2 -> 121740 | K33: =K32+J33 -> 19518980 | L33: =L32+(J33/$J$22) -> 0.10574713 | M33: TRANSFERÊNCIA VOLUNTÁRIA | N33: 12º BPM/M | O33: 2026NE00511 | P33: 11º TERMO ADITIVO nº CMM-37/40.2/26 | Q33: 46251 | R33: 46401 | S33: *** | T33: *** | V33: Conte Lopes | W33: 202602585846 | X33: 107487 | Y33: 20260434826 | AI33: Falta Publicar PNCP DOE SAI DIA 19/08
A34: 057.00357169/2026-11 | B34: CONTRATO COM GESTOR CONTRATO | C34: 2026NC19432 | D34: 2026NR00222 | F34: 365220 | G34: ---- | H34: 9 | I34: =I33+H34 -> 55 | J34: =H34*$I$2 -> 365220 | K34: =K33+J34 -> 19884200 | L34: =L33+(J34/$J$22) -> 0.12643678 | M34: TRANSFERÊNCIA VOLUNTÁRIA | N34: 43º BPM/M | O34: 2026NE00510 | P34: 12º TERMO ADITIVO nº CMM-38/40.2/26 | Q34: 46251 | R34: 46401 | S34: *** | T34: *** | V34: Conte Lopes | W34: 202602585852 | X34: 107481 | Y34: 20260434891 | AI34: Falta Publicar PNCP DOE SAI DIA 19/08
A35: 057.00357178/2026-01 | B35: CONTRATO COM GESTOR CONTRATO | C35: 2026NC19435 | D35: 2026NR00232 | E35: saiu 121.740,00 | F35: 243480 | G35: ---- | H35: 3 | I35: =I34+H35 -> 58 | J35: =H35*$I$2 -> 121740 | K35: =K34+J35 -> 20005940 | L35: =L34+(J35/$J$22) -> 0.13333333 | M35: TRANSFERÊNCIA VOLUNTÁRIA | N35: 12º BPM/M | O35: 2026NE00512 | P35: 13º TERMO ADITIVO nº CMM-39/40.2/26 | Q35: 46251 | R35: 46401 | S35: *** | T35: *** | V35: Danilo Campete | W35: 202632388097 | X35: 123560 | Y35: 20260435484 | AI35: Falta Publicar PNCP DOE SAI DIA 19/08
A36: 057.00357182/2026-61 | B36: CONTRATO COM GESTOR CONTRATO | C36: 2026NC19445 | D36: 2026NR00198 | F36: 284060 | G36: ---- | H36: 7 | I36: =I35+H36 -> 65 | J36: =H36*$I$2 -> 284060 | K36: =K35+J36 -> 20290000 | L36: =L35+(J36/$J$22) -> 0.14942529 | M36: TRANSFERÊNCIA VOLUNTÁRIA | N36: 43º BPM/M | O36: 2026NE00513 | P36: 14º TERMO ADITIVO nº CMM-40/40.2/26 | Q36: 46251 | R36: 46401 | S36: *** | T36: *** | V36: Conte Lopes | W36: 202502590853 | X36: 126572 | Y36: 20260438692 | AI36: Falta Publicar PNCP DOE SAI DIA 19/08
A37: 057.00357184/2026-51 | B37: CONTRATO COM GESTOR CONTRATO | C37: 2026NC19390 | D37: 2026NR00227 | F37: 243480 | G37: ---- | H37: 6 | I37: =I36+H37 -> 71 | J37: =H37*$I$2 -> 243480 | K37: =K36+J37 -> 20533480 | L37: =L36+(J37/$J$22) -> 0.16321839 | M37: TRANSFERÊNCIA VOLUNTÁRIA | N37: 28º BPM/I | O37: 2026NE00514 | P37: 15º TERMO ADITIVO nº CMM-41/40.2/26 | Q37: 46251 | R37: 46401 | S37: *** | T37: *** | V37: Guto Zacarias | W37: 202527585996 | X37: 117328 | Y37: 20260448812 | AI37: Falta Publicar PNCP DOE SAI DIA 19/08
A38: 057.00357237/2026-33 | B38: CONTRATO COM GESTOR CONTRATO | C38: 2026NC19393 | D38: 2026NR00184 | F38: 259784.95 | G38: ---- | H38: 3 | I38: =I37+H38 -> 74 | J38: =H38*$I$2 -> 121740 | K38: =K37+J38 -> 20655220 | L38: =L37+(J38/$J$22) -> 0.17011494 | M38: TRANSFERÊNCIA VOLUNTÁRIA | N38: 43º BPM/I | O38: 2026NE00507 | P38: 16º TERMO ADITIVO nº CMM-42/40.2/26 | Q38: 46251 | R38: 46401 | S38: *** | T38: *** | V38: Major Mecca | W38: 202605985052 | X38: 107509 | Y38: 20260435287 | AI38: Falta Publicar PNCP DOE SAI DIA 19/08
A39: 057.00357239/2026-22 | B39: PUBLICAÇÃO DO CONTRATO | C39: 2026NC19398 | D39: 2026NR00185 | F39: 121740 | G39: ---- | H39: 3 | I39: =I38+H39 -> 77 | J39: =H39*$I$2 -> 121740 | K39: =K38+J39 -> 20776960 | L39: =L38+(J39/$J$22) -> 0.17701149 | M39: TRANSFERÊNCIA VOLUNTÁRIA | N39: 40º BPM/I | O39: 2026NE00521 | P39: 17º TERMO ADITIVO nº CMM-43/40.2/26 | Q39: ? | V39: Maria Lúcia Amary | W39: 202606587951 | X39: 120394 | Y39: 20260435377 | AI39: Falta Publicar PNCP DOE SAI DIA 19/08
A40: 057.00357248/2026-13 | B40: CONTRATO COM GESTOR CONTRATO | C40: 2026NC19473 | D40: 2026NR00224 | F40: R$ 243.480,00 | G40: ---- | H40: 6 | I40: =I39+H40 -> 83 | J40: =H40*$I$2 -> 243480 | K40: =K39+J40 -> 21020440 | L40: =L39+(J40/$J$22) -> 0.1908046 | M40: TRANSFERÊNCIA VOLUNTÁRIA | N40: 21º BPM/M | O40: 2026NE00516 | P40: 18º TERMO ADITIVO nº CMM-44/40.2/26 | Q40: 46251 | R40: 46401 | S40: *** | T40: *** | V40: Marina Helou | W40: 202506690854 | X40: 126571 | Y40: 20260438712 | AI40: Falta Publicar PNCP DOE SAI DIA 19/08
A41: 057.00357251/2026-37 | B41: CONTRATO COM GESTOR CONTRATO | C41: 2026NC19474 | D41: 2026NR00204 | F41: R$ 243.480,00 | G41: ---- | H41: 6 | I41: =I40+H41 -> 89 | J41: =H41*$I$2 -> 243480 | K41: =K40+J41 -> 21263920 | L41: =L40+(J41/$J$22) -> 0.2045977 | M41: TRANSFERÊNCIA VOLUNTÁRIA | N41: 23º BPM/M | O41: 2026NE00515 | P41: 19º TERMO ADITIVO nº CMM-45/40.2/26 | Q41: 46251 | R41: 46401 | S41: *** | T41: *** | V41: Marina Helou | W41: 202506689696 | X41: 126083 | Y41: 20260435508 | AI41: Falta Publicar PNCP DOE SAI DIA 19/08
...

Sheet 3. SEDAN DESCARACTERIZA HB20
A1: PMESP-PRC | B1: PREGÃO | C1: NÚMERO DA ATA | F1: EMPRESA DETENTORA | G1: CNPJ | H1: DATA ASSINATURA ATA | I1: MATERIAL | J1: MARCA/MODELO | K1: VALOR UNITÁRIO | P1: QUANTIDADE DA ATA | Q1: ÓRGÃO GERENCIADOR | R1: DATA VALIDADE | S1: CABE PRORROGAÇÃO | T1: STATUS | U1: GESTOR DA ATA
A2: 057.00464676/2024-30 | B2: 90069/2024 | C2: DL nº 039/13/25 CMM n.º 00052/2025 | F2: HYUNDAI MOTOR BRASIL MONTADORA DE AUTOMOVEIS | G2: 10.394.422/0001-42 | H2: 15/10/2025 | I2: SEDAN DESCARACTERIZADA | J2: HYUNDAI/HB2O SEDAN | K2: 115680 | P2: 270 | Q2: CMM | R2: 46315 | S2: SIM | T2: VIGENTE | U2: Cap Monteiro
A5: Nº SEI DO ACIONAMENTO | B5: STATUS | C5: N.º NC | D5: N.º NR | E5: PTRES | F5: VALOR NC | G5: TOTAL ACIONADO | H5: ORIGEM DO RECURSO | I5: OPM BENEFICIADA | J5: N.º EMPENHO | K5: CONTRATO | L5: ASSINATURA DO CONTRATO | M5: PRAZO DE ENTREGA | N5: PRORROGAÇÃO PRAZO DE ENTREGA | O5: NOVO PRAZO DE ENTREGA | P5: PARLAMENTAR | Q5: Nº EMENDA ou CONVÊNIO | R5: Nº DEMANDA | S5: PROCESSO DEMANDA/ CÓDIGO ÚNICO | T5: CÓD. FONTE RECURSO | U5: EIXO | V5: TERMO DE ADESÃO | W5: AÇÃO | Y5: GESTOR CONTRATO | AA5: VALOR TOTAL | AC5: OBSERVAÇÕES SEÇ EXEC CONTRATUAL | AD5: TOTAL | AE5: REMANESCENTE | AF5: INSCRITO EM RPNP?
A6: 057.00256323/2026-20 | B6: CONTRATO COM GESTOR CONTRATO | C6: 2026NC09296 | D6: 2026NR00177 | E6: 180421 | F6: 115680 | G6: 1 | H6: EMENDA IMPOSITIVA | I6: CPI-3 | J6: 2026NE00428 | K6: 032/2026 | L6: 46232 | M6: 46382 | P6: Dep Rafael Silva | Q6: 202607582856 | R6: 102385 | S6: 20260370941 | T6: 150010001 | U6: ------------------- | V6: -------------------- | W6: ---------------------- | Y6: Cap Monteiro | AA6: =G6*K2 -> 115680 | AD6: =SUM(G6:G14) -> 7 | AE6: =P2-AD6 -> 263 | AG6: Falta PNCP
A7: 057.00268654/2026-11 | B7: CONTRATO COM GESTOR CONTRATO | C7: 2026NC15247 | D7: 2026NR00182 | E7: 180430 | F7: R$ 347.040,00 | G7: 3 | H7: TRANSFERÊNCIA VOLUNTÁRIA | I7: 1º BPChoq | J7: 2026NE00432 | K7: 031/2026 | L7: 46232 | M7: 46382 | P7: Tomé Abduch | Q7: 202528876123 | R7: 96858 | S7: 20260418520 | U7: ------------------- | V7: ------------------- | W7: ------------------- | Y7: Cap Monteiro | AA7: =G7*$K$2 -> 347040 | AG7: Falta PNCP
A8: 057.00268647/2026-19 | B8: CONTRATO COM GESTOR CONTRATO | C8: 2026NC15249 | D8: 2026NR00183 | E8: 180430 | F8: 115680 | G8: 1 | H8: TRANSFERÊNCIA VOLUNTÁRIA | I8: 53º BPM/I | J8: 2026NE00433 | K8: 030/2026 | L8: 46232 | M8: 46382 | P8: Dep. Conte Lopes | Q8: 202502579981 | R8: 100005 | S8: 20260418542 | U8: ------------------- | V8: ------------------- | W8: ------------------- | Y8: Cap Monteiro | AA8: =G8*$K$2 -> 115680 | AG8: Falta PNCP
A9: 057.00268392/2026-86 | B9: CONTRATO COM GESTOR CONTRATO | C9: 2026NC15240 | D9: 2026NR00181 | E9: 180430 | F9: 115680 | G9: 1 | H9: TRANSFERÊNCIA VOLUNTÁRIA | I9: CPI-2 | J9: 2026NE00431 | K9: 033/2026 | L9: 46232 | M9: 46382 | P9: Dep. Capitão Telhada | Q9: 202525675107 | R9: 96800 | S9: 20260418497 | Y9: Cap Monteiro | AA9: =G9*$K$2 -> 115680 | AG9: Falta PNCP
A10: 057.00376031/2026-11 | B10: AGUARDAN. ASS. CONTRATO | C10: 2026NC19441 | D10: 2026NR00193 | E10: 180430 | F10: 115680 | G10: 1 | H10: TRANSFERÊNCIA VOLUNTÁRIA | I10: 55º BPM/I | J10: 2026NE00526 | K10: 049/2026 | P10: Dep. Maria Lucia Amary | Q10: 202606587952 | R10: 120395 | S10: 20260435374 | AA10: =G10*$K$2 -> 115680
AA11: =G11*$K$2 -> 0
AA12: =G12*$K$2 -> 0
AA13: =G13*$K$2 -> 0
AA14: =G14*$K$2 -> 0

Sheet 4. MOTO SIPOM - KAWASAKIVERSYS 
A1: PMESP-PRC | B1: PREGÃO | C1: NÚMERO DA ATA | D1: EMPRESA | E1: CNPJ | F1: DATA ASSINATURA ATA | G1: MATERIAL - SERVIÇO | H1: MARCA/MODELO | I1: VALOR UNITÁRIO | J1: QUANTIDADE DA ATA | K1: DATA VALIDADE | L1: CABE PRORROGAÇÃO | M1: STATUS | N1: GESTOR DA ATA
A2: 057.00032652/2025-04 | B2: 90003/2025 | C2: DL nº 003/13/26 CMM nº 00030/2025 | D2: TRIPLE T DISTRIBUIDORA DE VEÍCULOS LTDA | E2: 16.625.187/0001-59 | F2: 03/02/2026 | G2: 180 MOTOCICLETAS descaracterizadas SIPOM | H2: KAWASAKI/VERSYS - X300 | I2: 35723.49 | J2: 180 | K2: 46422 | L2: SIM | M2: VIGENTE | N2: Cap Monteiro
A5: Nº SEI DO ACIONAMENTO | B5: STATUS | C5: N.º NC | D5: N.º NR | E5: PTRES | F5: VALOR NC | G5: TOTAL ACIONADO | H5: ORIGEM DO RECURSO | I5: OPM BENEFICIADA | J5: N.º EMPENHO | K5: PARLAMENTAR | L5: Nº EMENDA ou CONVÊNIO | M5: Nº DEMANDA | N5: PROCESSO DEMANDA | O5: Nº CONVÊNIO | P5: CÓD. FONTE RECURSO | Q5: EIXO | R5: TERMO DE ADESÃO | S5: AÇÃO | T5: GESTOR CONTRATO | U5: CONTRATO | V5: ASSINATURA DO CONTRATO | W5: PRAZO DE ENTREGA | X5: PRORROGAÇÃO PRAZO DE ENTREGA | Y5: NOVO PRAZO DE ENTREGA | Z5: OBSERVAÇÕES | AA5: TOTAL | AC5: INSCRITO EM RPNP?
A6: 057.00250483/2026-65 | B6: CONTRATO COM GESTOR CONTRATO | C6: 2026NC14964 | E6: 180430 | F6: R$ 20. 047. 200,00 ( SIPOM R$ 1.786,174,50 E RP/ ROCAM R$ 18.261.000,00) | G6: 50 | H6: EXCECUÇÃO ORDINÁRIA | I6: CMM | J6: 2026NE00305 | K6: ------------ | L6: ------------ | M6: ------------ | N6: ------------ | O6: ------------ | P6: 150010001 | Q6: ------------ | R6: ------------ | S6: ------------ | T6: TEN REBECA | U6: 012/40.2/26 | V6: 37798 | W6: 11622 | X6: *** | Y6: *** | Z6: NC DE MOTOS CARACTERIZADA JUNTA | AA6: 1786174.5

Sheet 14. SUV_CANIL - TRAILBLAZER 4X4
A1: PMESP-PRC | B1: PREGÃO | C1: NÚMERO DA ATA | D1: EMPRESA | E1: CNPJ | F1: DATA ASSINATURA ATA | G1: MATERIAL - SERVIÇO | H1: MARCA/MODELO | I1: VALOR UNITÁRIO | J1: QUANTIDADE DA ATA | P1: ÓRGÃO GERENCIADOR | Q1: DATA VALIDADE | R1: CABE PRORROGAÇÃO | S1: STATUS | T1: GESTOR DA ATA
A2: 057.00483409/2024-61 | B2: 90060/2024 | C2: DL nº 015/13/25 CMM nº 00026/2025 | D2: GENERAL MOTORS DO BRASIL LTDA | E2: 59.275.792/0001-50 (MATRIZ) | F2: 30/06/25 | G2: SUV Canil | H2: GM/TRAILBLAZER | I2: 311812.93 | J2: 27 | P2: CMM | Q2: 46569 | R2: SIM | S2: VIGENTE | T2: Cap Monteiro
A5: Nº SEI DO ACIONAMENTO | B5: STATUS | C5: N.º NR | D5: PTRES | E5: VALOR NC | F5: TOTAL ACIONADO | G5: ORIGEM DO RECURSO | H5: OPM BENEFICIADA | I5: N.º EMPENHO | J5: CONTRATO | K5: ASSINATURA DO CONTRATO | L5: PRAZO DE ENTREGA | M5: PRORROGAÇÃO PRAZO DE ENTREGA | N5: NOVO PRAZO DE ENTREGA | O5: DATA DA ENTREGA | P5: PARLAMENTAR | Q5: Nº EMENDA ou CONVÊNIO | R5: Nº DEMANDA | S5: PROCESSO DEMANDA | T5: Nº CONVÊNIO | U5: CÓD. FONTE RECURSO | V5: EIXO | W5: TERMO DE ADESÃO | X5: AÇÃO | Y5: GESTOR CONTRATO | Z5: VALOR TOTAL | AA5: VALOR TOTAL
A6: 057.00483409/2024-61 (Vol. IV) | E6: 1493500 | F6: 5 | J6: Contrato nº DL 026/13/25 (Gestor Maycon) | K6: 45841 | L6: 11287 | M6: 60 DIAS | N6: 11349 | O6: 46051 | Z6: Liquidado/Pago | AA6: 1493500

Sheet 6. FT_BAEP_TRAILBLAZER
A1: PMESP-PRC | B1: PREGÃO | C1: NÚMERO DA ATA | D1: EMPRESA | E1: CNPJ | F1: DATA ASSINATURA ATA | G1: MATERIAL | H1: MARCA/MODELO | I1: VALOR UNITÁRIO | J1: QUANTIDADE DA ATA | K1: DATA VALIDADE | Q1: CABE PRORROGAÇÃO | R1: GESTOR DA ATA
A2: 057.00446014/2024-88 | B2: 90046/2024 | C2: DL 003/11/25 CMM 00037/2024 | D2: General Motors do Brasil LTDA | E2: 59.275.792/0001-50 | F2: 04/02/2025 | G2: SUV FT/BAEP | H2: GM TRAIL BLAZER | I2: 273700 | J2: 400 | K2: 46059 | Q2: SIM | R2: CAP MONTEIRO
A5: Nº SEI DO ACIONAMENTO | B5: STATUS | C5: N.º NC | D5: N.º NR | E5: PTRES | F5: VALOR NC | G5: TOTAL ACIONADO | H5: ORIGEM DO RECURSO | I5: OPM BENEFICIADA | J5: N.º EMPENHO | K5: CONTRATO | L5: ASSINATURA DO CONTRATO | M5: PRAZO DE ENTREGA | N5: PRORROGAÇÃO PRAZO DE ENTREGA | O5: NOVO PRAZO DE ENTREGA | P5: DATA DA ENTREGA | Q5: PARLAMENTAR | R5: Nº EMENDA ou CONVÊNIO | S5: Nº DEMANDA | T5: PROCESSO DEMANDA | U5: Nº CONVÊNIO | V5: CÓD. FONTE RECURSO | W5: EIXO | X5: TERMO DE ADESÃO | Y5: AÇÃO | Z5: GESTOR CONTRATO | AA5: OBSERVAÇÕES UGE | AB5: OBSERVAÇÕES GESTÃO CONSTRATUAL
A6: 057.00446014/2024-88 (Vol. IV) | B6: PAGO | E6: 180430 | F6: 20801200 | G6: 76 | H6: EXCECUÇÃO ORDINÁRIA | J6: 2025NE00059 | K6: Contrato nº DL-010/13/25 | L6: 45740 | M6: 45890 | N6: *** | O6: *** | P6: VIDE OBSERVAÇÕES | V6: 150010001- TESOURO | Z6: Cap Maycon | AA6: PAGO | AB6: 24/ VIATURAS ENTREGUES EM 22/07/25; 25 VIATURAS ENTREGUES EM 23/07/25; 27 VIATURAS ENTREGUES EM 24/07/25;
A7: 057.00446014/2024-88 (Vol. V) | B7: PAGO | C7: 2025NC20556 | E7: 180430 | F7: 18885300 | G7: 69 | H7: FUNDO A FUNDO | J7: 2025NE00143 | K7: Contrato nº DL-025/13/25 | L7: 45841 | M7: 45991 | N7: *** | O7: *** | P7: VIDE OBSERVAÇÕES | V7: 275510001 | Z7: Cap Maycon | AA7: PAGO | AB7: 05 VIATURAS ENTREGUES EM 31/10/25; 05 VIATURAS ENTREGUES EM 03/11/25; 21 VIATURAS ENTREGUES EM 04/11/25; 16 VIATURAS ENTREGUES EM 05/11/25; 04 VIATURAS ENTREGUES EM 06/11/25; 08 VIATURAS ENTREGUES EM 07/11/25; 01 VIATURAS ENTREGUES EM 11/11/25; 05 VIATURAS ENTREGUES EM 12/11/25; 01 VIATURAS ENTREGUES EM 22/04/26 E 01 VIATURAS ENTREGUES EM 24/04/26
A8: 057.00446014/2024-88 (Vol. VI) | B8: PAGO | C8: 2025NC10491 | E8: 180430 | F8: 821100 | G8: 3 | H8: FUNDO A FUNDO | I8: 2º BAEP | J8: 2025NE00307 e 2025NE00308 | K8: Contrato nº DL-038/13/25 | L8: 45931 | M8: 46081 | N8: *** | O8: *** | P8: 46079 | V8: 275950003 | W8: Redução de Mortes Violentas Intencionais (RMVI); | Z8: TEN REBECA | AA8: Consta pago conforme Ofício n° DL-076/13/26 (0103743107) Porém o Processo de pagamento SEI 057.00109901/2026-30 não consta os documento de liquidação. | AB8: ****
A9: 057.00446014/2024-88 (Vol. VII) | B9: PAGO | C9: 2025NC10492 | E9: 180430 | F9: R$ 547.400,00 | G9: 2 | H9: EXCECUÇÃO ORDINÁRIA | J9: 2025NE00309 | K9: Contrato nº DL-063/13/25 | L9: 45931 | M9: 46081 | N9: *** | O9: *** | P9: 46080 | V9: 275510001 ( RECURSOS PROVENIENTES DE ALIENAÇÃO DE BENS) | Z9: Cap Maycon | AA9: PAGO | AB9: ****
A10: 057.00571983/2025-57 | B10: PAGO | E10: 180430 | F10: 1368500 | G10: 5 | H10: EXCECUÇÃO ORDINÁRIA | J10: 2025NE00438 | K10: Contrato nº DL-093/13/25 | L10: 45994 | M10: 46144 | N10: *** | O10: *** | P10: VIDE OBSERVAÇÕES | V10: 175920035 | Z10: TEN REBECA | AA10: PENDENTE de liquidação/Pagamento (Inscrito em RPNP), referente a NE nº 2025NE00438. | AB10: 04 VIATURAS ENTREGUES EM 30/03/26 E 01 VIATURA ENTREGUE EM 22/04/26
A11: 057.00578977/2025-21 | E11: 180430 | F11: 273700 | G11: 1 | H11: EXCECUÇÃO ORDINÁRIA | J11: 2025NE00447 | K11: Contrato nº DL-102/13/25 | L11: 45994 | M11: 46144 | N11: *** | O11: *** | P11: 46111 | V11: 2755100001 | Z11: TEN REBECA | AA11: PENDENTE de liquidação/Pagamento (Inscrito em RPNP), referente a NE nº 2025NE00447.
A12: 057.00594223/2025-18 | B12: PAGO | E12: 180430 | F12: 821100 | G12: 3 | H12: EXCECUÇÃO ORDINÁRIA | J12: 2025NE00467 | K12: Contrato nº DL-106/13/25 | L12: 46010 | M12: 46160 | N12: *** | O12: *** | P12: 46155 | V12: 170650014 | Z12: TEN REBECA | AA12: PAGO
A13: 057.00060684/2026-72 (Nota de Empenho Cancelada, Pórem não consta no referido processo) | B13: CANCELADO | E13: 180421 | F13: 273700 | G13: 1 | J13: 2026NE00019 | K13: Contrato nº DL-006/13/26 | Q13: DEP REIS | R13: 202628478047 | S13: 101667 | V13: 1500100001 | Z13: TEN REBECA | AA13: Conforme Proc. SEI N° 057.00060684/2026-72. Consta NE 2026NE00019. Porém não consta nota de cancelamento.

Sheet 8. RE PCD - FIAT SCUDO
A1: PMESP-PRC | B1: PREGÃO | C1: NÚMERO DA ATA | F1: DATA ASSINATURA ATA | G1: MATERIAL - SERVIÇO | H1: MARCA/MODELO | I1: VALOR UNITÁRIO | J1: QUANTIDADE DA ATA | K1: ÓRGÃO GERENCIADOR | Q1: DATA VALIDADE | R1: CABE PRORROGAÇÃO | S1: STATUS | T1: GESTOR DA ATA
A2: 057.00413638/2024-19 | B2: Nº 90039/2024 | C2: DL nº 011/11/25 CMM nº 00041/2024 | F2: 06/05/2025 | G2: VIATURA PARA RONDA ESCOLAR ADAPTADA PARA PESSOA COM DEFICIÊNCIA (PCD) | H2: FIAT/SCUDO MULTI 2.2 2025/2025 | I2: R$ 289.800,00 | J2: 44 | K2: CMM | Q2: 46149 | R2: SIM | S2: FINALIZADA | T2: Cap Monteiro
R3: NAO HOUVE INTERESSE RENOVACAO CAP MONTEIRO
