Workbook

Sheet VTR AGUARDANDO VISTORIA
A1: OS | B1: PLACA | C1: ANO | D1: MARCA/MODELO | E1: UNIDADE | F1: PREFIXO | G1: DATA DE ENTRADA NA LINHA | H1: TEMPO PARADA | I1: PROBLEMA RELATADO | J1: DATA DE SAÍDA | K1: DESTINO | L1: KM
A2: 17198 | B2: DMM7139 | D2: SPIN | E2: 16º BPM/M | F2: M-16330 | G2: 46027 | H2: 0 | I2: GRAFISMO | J2: 46027 | K2: GRAFISMO
A3: 18164 | B3: REV4E94 | C3: 2022 | D3: CHEV/S10 LT DD4A | E3: CMB | F3: 15-47 | G3: 46174 | H3: 0 | I3: • TROCA DOS QUATRO PNEUS 265/60R18. (REMANEJADOS). | J3: 46174 | K3: LIBERADO | L3: 68335
A4: 18244 | B4: CFY5823 | C4: 2013 | D4: TOYOTA/HILUX SW4 4X2SR | E4: APMTJ | F4: 3-145 | G4: 46188 | H4: 0 | I4: AVALIAÇÃO PARA CONTRATAÇÃO | J4: 46189 | K4: CONTRATAÇÃO | L4: 175283
A5: 17202 | B5: DJL9479 | D5: XRE300 | E5: 26ºBPMM | F5: M-26482 | G5: 46028 | H5: 1 | I5: SINALIZADOR | J5: 46029 | K5: SINALIZADOR
A6: 18405 | B6: FPI3C61 | C6: 2022 | D6: CHEV/TRAILBLAZER LT | E6: CAJ | F6: 1-28 | G6: 46219 | H6: 0 | I6: • AVALIAÇÃO. • AVALIAÇÃO.. • AVALIAÇÃO DEVOLUÇÃO SAF. • INJEÇÃO ELETRÔNICA - RESET VIA SCANNER. • INSPEÇÃO GERAL VTR - SEM NOVIDADES. • AVALIAÇÃO DEVOLUÇÃO SAF. • INJEÇÃO ELETRÔNICA - RESET VIA SCANNER. • INSPEÇÃO GERAL VTR - SEM NOVIDADES. | J6: 46220 | K6: LINHA MECÂNICA LIBERADO | L6: 219196
A7: 18163 | B7: REV4E91 | C7: 2022 | D7: CHEV/S10 LT DD4A | E7: DTIC | F7: 15-49 | G7: 46174 | H7: 0 | I7: . TROCA DE DOIS PNEUS 265/60R18 (REMANEJAMENTO) | J7: 46174 | K7: CONTRATAÇÃO | L7: 82203
A8: 17206 | B8: CKH2F73 | C8: 2021 | D8: TRAILBLAZER | E8: PMRG | F8: 17-461 | G8: 46028 | H8: 1 | I8: TROCA DE PASTILHAS FREIO DIANT. REVISÃO ELETRICA | J8: 46029 | K8: MECÂNICA
A9: 17208 | B9: BYQ7C54 | C9: 2022 | D9: TRAIBLAZER | E9: PMRG | F9: 17-462 | G9: 46028 | H9: 3 | I9: TROCA PASTILHAS FREIO DIANTEIRAS | J9: 46031 | K9: MECÂNICA
A10: 17209 | B10: FXS1E37 | D10: TRAIBLAZER | E10: EM PM | F10: 1-80 | G10: 46028 | H10: 0 | I10: SETOR TÉCNICO | J10: 46028 | K10: SETOR TÉCNICO
A11: 18084 | B11: SUF6A36 | C11: 2023 | D11: VW/17.230 OD | E11: CMM | F11: 7-47 | G11: 46163 | H11: 126 | I11: SOLDA DO ESCAPAMENTO | J11: 46188 | K11: LIBERADO | L11: 38911
A12: 17215 | B12: EXN4482 | D12: GOL | E12: 26º BPM/I | F12: I-26340 | G12: 46030 | H12: 53 | I12: PERÍCIA | J12: 46083 | K12: PERÍCIA
A13: 17216 | B13: EGI4246 | C13: 2020 | D13: SW4 | E13: CIPM | F13: 15-17 | G13: 46030 | H13: 0 | I13: BORRACHARIA | J13: 46030 | K13: BORRACHARIA
A14: 17217 | B14: GBG9B73 | D14: SPIN | E14: 34º BPM/I | F14: I-34105 | G14: 46030 | H14: 0 | I14: SINALIZADOR | J14: 46030 | K14: SINALIZADOR
A15: 17218 | B15: FUQ0566 | D15: SPIN | E15: 38º BPM/M | F15: 26-530 | G15: 46030 | H15: 5 | I15: SINALIZADOR | J15: 46035 | K15: SINALIZADOR
A16: 17219 | B16: CSP6C81 | C16: 2022 | D16: TRAILBLAZER | E16: GABCMTG | F16: 1-44 | G16: 46030 | H16: 0 | I16: MECÂNICA | J16: 46030 | K16: MECÂNICA
A17: 18387 | B17: CUE7E86 | C17: 2022 | D17: CHEV/TRAILBLAZER LT | E17: CMT GERAL | F17: 15-74 | G17: 46217 | H17: 4 | I17: • TROCA DE DOIS PNEUS 265/60/18. • ALINHAMENTO DE DIREÇÃO. • BALANCEAMENTO DE RODAS. | J17: 46219 | K17: BORRACHARIA LIBERADO | L17: 69087
A18: 17221 | B18: CFY5F18 | D18: HILUX | E18: EEF | F18: 3-325 | G18: 46030 | H18: 0 | I18: VIATURA NÃO FUNCIONA (MOTOR) | J18: 46030 | K18: MECÂNICA/SINAL
A19: 18413 | B19: CJJ7F93 | C19: 2022 | D19: CHEV/TRAILBLAZER LT | E19: APMTJ | F19: 1-61 | G19: 46220 | H19: 0 | I19: • AVALIAÇÃO PARA CONTRATAÇÃO. • REVISÃO DOS 100 MIL/KM. | J19: 46223 | K19: LINHA MECÂNICA CONTRATAÇÃO | L19: 98306
A20: 17223 | B20: FEQ9H11 | D20: TRAILBLAZER | E20: 25º BPM/M | F20: M-25171 | G20: 46030 | H20: 0 | I20: SINALIZADOR | J20: 46030 | K20: SINALIZADOR
A21: 17225 | B21: GGO3962 | C21: 2018 | D21: TRAILBLAZER | E21: EEF | F21: EEF-004 | G21: 46030 | H21: 6 | I21: TROCA DE BATERIA E AS 3 PALHETAS | J21: 46036 | K21: MECÂNICA
A22: 17227 | B22: GFO7I66 | C22: 2022 | D22: TRAILBLAZER | E22: SAF | F22: 15-298 | G22: 46030 | H22: 4 | I22: TROCA BATERIA (REVISÃO FREIOS, FLUIDOS E FILTROS, OK) | J22: 46034 | K22: MECÂNICA
A23: 17229 | B23: EEF9580 | C23: 2014 | D23: COROLLA | E23: SENASP | F23: 15-241 | G23: 46030 | H23: 0 | I23: TROCA DE BATERIA | J23: 46030 | K23: MECÂNICA
A24: 17231 | B24: DJM8692 | C24: 2014 | D24: CRUZE | E24: CMED | F24: 15-114 | G24: 46030 | H24: 126 | I24: BATERIA, ARREFECIMENTO | K24: MECÂNICA
A25: 18061 | B25: EDI2I97 | C25: 2021 | D25: RENAULT/MASTER L2H2 MNPA | E25: C MED | F25: 5-24 | G25: 46161 | H25: 4 | I25: • CARGA NA BATERIA. • MUDANÇA DA INSTALAÇÃO DO RADIO OPERACIONAL NA BATERIA AUXILIAR. | J25: 46164 | K25: LIBERADO | L25: 20505
A26: 17233 | B26: EEF8705 | C26: 2014 | D26: S-10 | E26: CMB | F26: 3-59 | G26: 46030 | H26: 1 | I26: TROCA DE BATERIA E REVISÃO ELÉTRICA | J26: 46031 | K26: MECÂNICA/SINAL
A27: 17234 | B27: DFL7906 | D27: XRE300 | E27: 39ºBPMM | F27: M-39380 | G27: 46031 | H27: 125 | I27: GRAFISMO | K27: GRAFISMO
A28: 17235 | B28: DJL9246 | D28: XRE300 | E28: 39ºBPMM | F28: M-39381 | G28: 46031 | H28: 0 | I28: GRAFISMO | J28: 46031 | K28: GRAFISMO
A29: 17237 | B29: FRU3184 | C29: 2015 | D29: SPIN | E29: DL | F29: 22-523 | G29: 46031 | H29: 6 | I29: REAPERTO TERMINAL BATERIA | J29: 46037 | K29: MECÂNICA
A30: 17239 | B30: BOT5I18 | D30: LANDER | E30: CMM | F30: 19-2 | G30: 46034 | H30: 3 | I30: MECÂNICA | J30: 46037 | K30: MECÂNICA
A31: 17240 | B31: DJL1175 | D31: GOL | E31: DEC | F31: 15-209 | G31: 46034 | H31: 0 | I31: BORRACHARIA | J31: 46034 | K31: BORRACHARIA
A32: 18316 | B32: FPF0B04 | C32: 2022 | D32: CHEV/TRAILBLAZER LT | E32: EM/PM | F32: 1-81 | G32: 46198 | H32: 0 | I32: . TROCA DA LAMPADA H7 | J32: 46204 | K32: LINHA MECÂNICA LIBERADO | L32: 41538
A33: 17242 | B33: GCP4F05 | C33: 2022 | D33: TRAILBLAZER | E33: SAF | F33: 1-84 | G33: 46034 | H33: 0 | I33: TROCA DO PARA-BRISA COM GUARNIÇÃO, APLICAÇÃO DE PELÍCULA INSULFILM NO PARA-BRISA, TROCA DAS LAMPADAS DE MEIA-LUZ E LANTERNA TRAZEIRA (LED). | J33: 46034 | K33: MECÂNICA
A34: 18057 | B34: FNA3823 | C34: 2017 | D34: CHEV/SPIN 1.8L MT LT | E34: COPOM | F34: 22-296 | G34: 46160 | H34: 21 | I34: REPAROS NO CHICOTE E TROCA DE RELE AUXILIAR | J34: 46160 | K34: LIBERADO | L34: 95254
A35: 17244 | B35: EEF8992 | C35: 2014 | D35: SPACEFOX | E35: COPOM | F35: 22-69 | G35: 46034 | H35: 24 | I35: BATERIA, SENSOR DO ACELERADOR. | J35: 46058 | K35: MECÂNICA
A36: 17245 | B36: EEF9606 | C36: 2014 | D36: COROLLA | E36: SAF | F36: 1-168 | G36: 46034 | H36: 0 | I36: TROCA PARA-BARROS LD E LE, LENTES FAROIS DE NEBLINA, MAÇANETA PORTA TRAZ LD | J36: 46034 | K36: MECÂNICA
A37: 17246 | B37: FTI7A82 | D37: DUSTER | E37: 50ºBPMI | F37: I-50248 | G37: 46035 | H37: 0 | I37: SINALIZADOR | J37: 46035 | K37: SINALIZADOR
A38: 17247 | B38: EYK7132 | D38: SPIN | E38: 47ºBPMI | F38: I-47616 | G38: 46035 | H38: 45 | I38: SETOR TÉCNICO | J38: 46080 | K38: SETOR TÉCNICO
A39: 17248 | B39: FQB5482 | C39: 2015 | D39: COBALT | E39: APMAL | F39: 15-203 | G39: 46035 | H39: 0 | I39: CONTRATAÇÃO CONFORME OFÍCIO | J39: 46035 | K39: MECÂNICA
A40: 17249 | B40: GCI9C06 | D40: TRAILBLAZER | E40: 13º BPM/M | F40: M-13019 | G40: 46035 | H40: 0 | I40: GRAFISMO | J40: 46035 | K40: GRAFISMO
...

Sheet VTR DESCARGA
A1: OS | B1: PLACA | C1: ANO | D1: MARCA/MODELO | E1: UNIDADE | F1: Prefixo | G1: DATA DE ENTRADA NA LINHA | H1: TEMPO PARADA | I1: PROBLEMA RELATADO | J1: DATA DE SAÍDA | K1: DESTINO
A2: 10712 | B2: DJL2441 | C2: 2012 | D2: PALIO WEEK | E2: DPCDH | F2: 22-337 | G2: 45271 | H2: =IF(G2="","",IF(J2="",TODAY()-G2,J2-G2)) -> 182 | I2: ESCAPAMENTO/CAIXA E BOMBA DE DIREÇÃO/PNEUS | J2: 45453 | K2: CONTRATAÇÃO - DESCARGA
A3: 11547 | B3: EEF4106 | C3: 2009 | D3: ASTRA | E3: CMM | F3: 22-330 | G3: 45344 | H3: =IF(G3="","",IF(J3="",TODAY()-G3,J3-G3)) -> 110 | I3: VAZAMENTO COMB/ MOTOR Ñ FUNCIONA/ CHEIRO EMBR. CAMBIO/ COXINS AMORTECEDORES/ VERIFICAR CORREIAS/ AR INOPERANTE | J3: 45454 | K3: CONTRATAÇÃO - DESCARGA
A4: 11840 | B4: GBO4311 | C4: 2017 | D4: SPIN | E4: APMTJ | F4: 22-89 | G4: 45359 | H4: =IF(G4="","",IF(J4="",TODAY()-G4,J4-G4)) -> 95 | I4: CONSUMO ÓLEO / BARULHO NA SUSPENSÃO | J4: 45454 | K4: CONTRATAÇÃO - DESCARGA
A5: 11680 | B5: CFY5839 | C5: 2014 | D5: TRAILBLAZER | E5: DTIC | F5: 3-424 | G5: 45352 | H5: =IF(G5="","",IF(J5="",TODAY()-G5,J5-G5)) -> 104 | I5: SUSPENSÃO/ FREIO/ CAMBIO | J5: 45456 | K5: CONTRATAÇÃO - DESCARGA
A6: 11273 | B6: DJL0953 | C6: 2008 | D6: KOMBI | E6: CAVPM | F6: 3-168 | G6: 45321 | H6: =IF(G6="","",IF(J6="",TODAY()-G6,J6-G6)) -> 136 | I6: CAMBIO/ MOTOR/ SUSPENSÃO | J6: 45457 | K6: CONTRATAÇÃO - DESCARGA
A7: 11908 | B7: CFY5799 | C7: 2013 | D7: HILUX | E7: ESSD | F7: 3-37 | G7: 45363 | H7: =IF(G7="","",IF(J7="",TODAY()-G7,J7-G7)) -> 97 | I7: SUSPENSÃO/ FREIO/ MOTOR/ CAMBIO | J7: 45460 | K7: CONTRATAÇÃO - DESCARGA
A8: 11906 | B8: FXR6994 | C8: 2017 | D8: PALIO WEEK | E8: ESSD | F8: 22-315 | G8: 45363 | H8: =IF(G8="","",IF(J8="",TODAY()-G8,J8-G8)) -> 97 | I8: SUSPENSÃO/ FREIO/ MOTOR/ CAMBIO | J8: 45460 | K8: CONTRATAÇÃO - DESCARGA
A9: 11595 | B9: DJL6019 | C9: 2011 | D9: BLAZER | E9: CMM | F9: 15-16 | G9: 45348 | H9: =IF(G9="","",IF(J9="",TODAY()-G9,J9-G9)) -> 113 | I9: ELÉTRICO ( VTR ENCHENTE DO CMM ) | J9: 45461 | K9: CONTRATAÇÃO - DESCARGA
A10: 12999 | B10: FJH5857 | C10: 2017 | D10: PALIO WEEK | E10: CMM | F10: 22-1092 | G10: 45453 | H10: =IF(G10="","",IF(J10="",TODAY()-G10,J10-G10)) -> 8 | I10: LUZ ANOMALIA ACESA ( BAIXA PRESSÃO DE ÓLEO ) | J10: 45461 | K10: CONTRATAÇÃO - DESCARGA
A11: 11574 | B11: DJM0137 | C11: 2011 | D11: PARATI | E11: CMM | F11: 22-631 | G11: 45344 | H11: =IF(G11="","",IF(J11="",TODAY()-G11,J11-G11)) -> 295 | I11: REVISÃO GERAL | J11: 45639 | K11: CONTRATAÇÃO - DESCARGA
A12: 12454 | B12: GAT6417 | C12: 2018 | D12: SPIN | E12: EEF | F12: 22-1184 | G12: 45404 | H12: =IF(G12="","",IF(J12="",TODAY()-G12,J12-G12)) -> 235 | I12: CAMBIO NÃO ENGATA 3º MARCHA | J12: 45639 | K12: CONTRATAÇÃO - DESCARGA
A13: 12492 | B13: GAC3646 | C13: 2015 | D13: SPIN | E13: DEC | F13: 22-382 | G13: 45406 | H13: =IF(G13="","",IF(J13="",TODAY()-G13,J13-G13)) -> 233 | I13: CHAVE QUEBRADA/ PAINEL DEFEITUOSO/ ARREFECIMENTO/ PANE ELÉTRICA | J13: 45639 | K13: CONTRATAÇÃO - DESCARGA
A14: 202/24 | B14: FCF9549 | C14: 2017 | D14: PALIO WEEK | E14: DF/CIAP | F14: 22-1308 | G14: 45489 | H14: =IF(G14="","",IF(J14="",TODAY()-G14,J14-G14)) -> 150 | I14: BATERIA/ PANE ELETRICA/ MOTOR RAJANDO | J14: 45639 | K14: CONTRATAÇÃO - DESCARGA
A15: 13788 | B15: EEF5753 | C15: 2010 | D15: PARATI | E15: CAPS | F15: 15-351 | G15: 45534 | H15: =IF(G15="","",IF(J15="",TODAY()-G15,J15-G15)) -> 47 | I15: SUSPENSÃO. MOTOR , FREIO | J15: 45581 | K15: CONTRATAÇÃO - DESCARGA
A16: 14-477 | B16: FOF9372 | C16: 2017 | D16: SPIN | E16: CMM-SAF | F16: 22-336 | G16: 45628 | H16: =IF(G16="","",IF(J16="",TODAY()-G16,J16-G16)) -> 80 | I16: DIREÇÃO ELÉTRICA, PAINEL. PANE ELETRICA | J16: 45708 | K16: CONTRATAÇÃO - DESCARGA
A17: 14465 | B17: EEF9238 | C17: 2014 | D17: SPACEFOX | E17: CMM/SAF | F17: 22-1306 | G17: 45624 | H17: =IF(G17="","",IF(J17="",TODAY()-G17,J17-G17)) -> 89 | I17: POSSÍVEL DESCARGA | J17: 45713 | K17: CONTRATAÇÃO - DESCARGA
A18: 14825 | B18: GBA6310 | C18: 2015 | D18: SPIN | E18: APMBB | F18: BA-046 | G18: 45681 | H18: =IF(G18="","",IF(J18="",TODAY()-G18,J18-G18)) -> 69 | I18: MOTOR QUEIMANDO ÓLEO | J18: 45750 | K18: CONTRATAÇÃO - DESCARGA
A19: 15423 | B19: GBZ0400 | C19: 2015 | D19: SPIN | E19: ESSD | F19: ESSD-057 | G19: 45747 | H19: =IF(G19="","",IF(J19="",TODAY()-G19,J19-G19)) -> 43 | I19: REVISÃO GERAL | J19: 45790 | K19: CONTRATAÇÃO - DESCARGA
A20: 15464 | B20: EEF5758 | C20: 2010 | D20: PARATI | E20: CMM - SAF | F20: 22-731 | G20: 45750 | H20: =IF(G20="","",IF(J20="",TODAY()-G20,J20-G20)) -> 53 | I20: AVALIAÇÃO DE RECOLHA | J20: 45803 | K20: CONTRATAÇÃO - DESCARGA
A21: 15744 | B21: FWP1363 | C21: 2018 | D21: SPIN | E21: CPC | F21: 22-824 | G21: 45785 | H21: =IF(G21="","",IF(J21="",TODAY()-G21,J21-G21)) -> 46 | I21: FALHA MOTOR | J21: 45831 | K21: CONTRATAÇÃO - DESCARGA
A22: 15749 | B22: CMW7425 | C22: 2010 | D22: VECTRA | E22: C MED | F22: 15-131 | G22: 45785 | H22: =IF(G22="","",IF(J22="",TODAY()-G22,J22-G22)) -> 46 | I22: REVISÃO GERAL, PNEUS, MOTOR, FREIO | J22: 45831 | K22: CONTRATAÇÃO - DESCARGA
A23: 15762 | B23: CMW7379 | C23: 2010 | D23: VECTRA | E23: SAF | F23: 15-124 | G23: 45786 | H23: =IF(G23="","",IF(J23="",TODAY()-G23,J23-G23)) -> 94 | I23: MOTOR/SUSPENSÃO/DERIVADOS | J23: 45880 | K23: CONTRATAÇÃO - DESCARGA
A24: 16193 | B24: CDV3430 | C24: 2002 | D24: KOMBI | E24: C ODONT | F24: 3-1081 | G24: 45852 | H24: =IF(G24="","",IF(J24="",TODAY()-G24,J24-G24)) -> 28 | I24: CAMBIO / SUSPENSÃO / PNEUS | J24: 45880 | K24: CONTRATAÇÃO - DESCARGA
A25: 16295 | B25: CMW7432 | C25: 2010 | D25: VECTRA | E25: CAJ PM | F25: 15-191 | G25: 45868 | H25: =IF(G25="","",IF(J25="",TODAY()-G25,J25-G25)) -> 13 | I25: REVISÃO GERAL. | J25: 45881 | K25: CONTRATAÇÃO - DESCARGA
A26: 16399 | B26: CMW7426 | C26: 2010 | D26: VECTRA | E26: C COM SOC | F26: 15-164 | G26: 45882 | H26: =IF(G26="","",IF(J26="",TODAY()-G26,J26-G26)) -> 2 | I26: ESCAPAMENTO, SUSPENSÃO. REVISÃO GERAL. | J26: 45884 | K26: CONTRATAÇÃO - DESCARGA
A27: 16188 | B27: CMW7386 | C27: 2010 | D27: VECTRA | E27: C COM SOC | F27: 15-146 | G27: 45849 | H27: =IF(G27="","",IF(J27="",TODAY()-G27,J27-G27)) -> 35 | I27: SUSPENSÃO, CAMBIO | J27: 45884 | K27: CONTRATAÇÃO - DESCARGA
A28: 16224 | B28: CMW7420 | C28: 2010 | D28: VECTRA | E28: COPOM | F28: 15-161 | G28: 45855 | H28: =IF(G28="","",IF(J28="",TODAY()-G28,J28-G28)) -> 29 | I28: SISTEMA ELETRICO/MOTOR/SUSPENSÃO | J28: 45884 | K28: CONTRATAÇÃO - DESCARGA
... A30: 16010 | B30: FDB4938 | C30: 2018 | D30: SPIN | E30: SAF | F30: 17-16 | G30: 45820 | H30: =IF(G30="","",IF(J30="",TODAY()-G30,J30-G30)) -> 64 | I30: ELÉTRICO/ MOTOR | J30: 45884 | K30: CONTRATAÇÃO - DESCARGA
A31: 16011 | B31: BYZ7654 | C31: 2018 | D31: SPIN | E31: SAF | F31: 45947 | G31: 45820 | H31: =IF(G31="","",IF(J31="",TODAY()-G31,J31-G31)) -> 64 | I31: REVISAO GERAL | J31: 45884 | K31: CONTRATAÇÃO - DESCARGA
A32: 16653 | B32: FPZ5988 | C32: 2018 | D32: PALIO W | E32: SAF | F32: 22-93 | G32: 45923 | H32: =IF(G32="","",IF(J32="",TODAY()-G32,J32-G32)) -> 57 | I32: VIATURA COM SUPERAQUECIMENTO/ AVALIAÇÃO PARA DESCARGA | J32: 45980 | K32: CONTRATAÇÃO - DESCARGA
A33: 16812 | B33: GAV2510 | C33: 2015 | D33: SPIN | E33: CMED | F33: 22-750 | G33: 45945 | H33: =IF(G33="","",IF(J33="",TODAY()-G33,J33-G33)) -> 40 | I33: DESCARGA | J33: 45985 | K33: CONTRATAÇÃO - DESCARGA
A34: 16676 | B34: FAT4978 | C34: 2015 | D34: SPIN | E34: DTIC | F34: 22-741 | G34: 45925 | H34: =IF(G34="","",IF(J34="",TODAY()-G34,J34-G34)) -> 60 | I34: DESCARGA | J34: 45985 | K34: CONTRATAÇÃO - DESCARGA
A35: 16667 | B35: DJL7764 | C35: 2010 | D35: BLAZER | E35: DSACG | F35: 15-92 | G35: 45925 | H35: =IF(G35="","",IF(J35="",TODAY()-G35,J35-G35)) -> 300 | I35: AVALIAÇÃO PARA POSSÍVEL DESCARGA | K35: CONTRATAÇÃO - DESCARGA
A36: 16676 | B36: FAT4978 | C36: 2015 | D36: SPIN | E36: DTIC | F36: 22-741 | G36: 45925 | H36: =IF(G36="","",IF(J36="",TODAY()-G36,J36-G36)) -> 300 | I36: PORTA DO MOTORISTA NÃO ABRE POR DENTRO, FALHA NO MOTOR, PNEU TRASEIRO FURADO | K36: CONTRATAÇÃO - DESCARGA
A37: 16784 | B37: GBK4005 | C37: 2015 | D37: SPIN | E37: CMM | F37: 22-684 | G37: 45940 | H37: =IF(G37="","",IF(J37="",TODAY()-G37,J37-G37)) -> 285 | I37: ARREFECIMENTO/ VIATURA NÃO LIGA POSSÍVEL BATERIA | K37: CONTRATAÇÃO - DESCARGA
A38: 16812 | B38: GAV2510 | C38: 2015 | D38: SPIN | E38: CMED | F38: 22-750 | G38: 45945 | H38: =IF(G38="","",IF(J38="",TODAY()-G38,J38-G38)) -> 280 | I38: FREIO; SUSPENSÃO ; DIREÇÃO; | K38: CONTRATAÇÃO - DESCARGA
A39: 16787 | B39: EEF8713 | C39: 2014 | D39: COROLLA | E39: SAF | F39: 15-14 | G39: 45943 | H39: =IF(G39="","",IF(J39="",TODAY()-G39,J39-G39)) -> 282 | I39: REVISÃO GERAL (POSSIVEL DESCARGA) | K39: CONTRATAÇÃO - DESCARGA
A40: 16790 | B40: DJL7766 | C40: 2011 | D40: BLAZER | E40: DTIC | F40: 15-93 | G40: 45943 | H40: =IF(G40="","",IF(J40="",TODAY()-G40,J40-G40)) -> 282 | I40: REVISÃO GERAL | K40: CONTRATAÇÃO - DESCARGA
A41: 16812 | B41: GAV2510 | C41: 2015 | D41: SPIN | E41: CMED | F41: 22-750 | G41: 45945 | H41: =IF(G41="","",IF(J41="",TODAY()-G41,J41-G41)) -> 280 | I41: REVISÃO SUSPENSÃO, FREIOS, PNEUS, ALINHAMENTO E BALANCEAMENTO. | K41: CONTRATAÇÃO - DESCARGA
...

Sheet VTR PRONTA
A1: O.S. | B1: PLACA | C1: ANO | D1: MARCA/MODELO | E1: UNIDADE | F1: Prefixo | G1: DATA DE ENTRADA NA LINHA | H1: TEMPO PARADA | I1: PROBLEMA RELATADO | J1: DATA DE SAÍDA | K1: DESTINO
A2: 0 | B2: STT7I41 | C2: 2023 | D2: COROLLA | E2: 05 BPMM | F2: M-05365 | G2: 45625 | H2: =IF(G2="","",IF(J2="",TODAY()-G2,J2-G2)) -> 0 | I2: APOIO OPERAÇÃO VERÃO TROCA DE PNEU DIANTEIRO DIREITO | J2: 45625 | K2: REPARADO - LIBERADA
A3: 0 | B3: SVO9C79 | C3: 2023 | D3: COROLLA | E3: 05 BPMM | F3: M-05371 | G3: 45625 | H3: =IF(G3="","",IF(J3="",TODAY()-G3,J3-G3)) -> 0 | I3: APOIO OPERAÇÃO VERÃO TROCA DE PNEU DIANTEIRO ESQUERDO | J3: 45625 | K3: REPARADO - LIBERADA
A4: 0 | B4: ECO5J34 | C4: 2022 | D4: TRAILBLAZER | E4: BAEP | F4: E-07218 | G4: 45660 | H4: =IF(G4="","",IF(J4="",TODAY()-G4,J4-G4)) -> 0 | I4: VISTORIA PARA OPERAÇÃO VERÃO/ | J4: 45660 | K4: CONTRATAÇÃO
A5: 0 | B5: FSB7D43 | C5: 2020 | D5: TRAILBLEZER | E5: BAEP | F5: E-07111 | G5: 45660 | H5: =IF(G5="","",IF(J5="",TODAY()-G5,J5-G5)) -> 0 | I5: VISTORIA PARA OPERAÇÃO VERÃO/ REPROVADA; PNEUS DIANEIROS E TRASEIROS E TROCA DE ÓLEO | J5: 45660 | K5: REPARADO - LIBERADA
A6: 0 | B6: DII9749 | C6: 2019 | D6: SPIN | E6: 5BPM/M | F6: 5337 | G6: 45775 | H6: =IF(G6="","",IF(J6="",TODAY()-G6,J6-G6)) -> 0 | I6: VISTORIA DE RECOLHA (REPROVADA) | J6: 45775 | K6: REPARADO - LIBERADA
A7: 0 | B7: DSR8379 | C7: 2019 | D7: SPIN | E7: 5ºBPM/M | F7: M-05339 | G7: 45775 | H7: =IF(G7="","",IF(J7="",TODAY()-G7,J7-G7)) -> 0 | I7: VISTORIA DE RECOLHA - APROVADA | J7: 45775 | K7: REPARADO - LIBERADA
A8: 0 | B8: BSX7I45 | C8: 2019 | D8: DUSTER | E8: 9BPM/M | F8: 9219 | G8: 45775 | H8: =IF(G8="","",IF(J8="",TODAY()-G8,J8-G8)) -> 0 | I8: REAVALIAÇÃO DE RECOLHA (APROVADA) | J8: 45775 | K8: REPARADO - LIBERADA
A9: 6276 | B9: DJM8798 | C9: 2013 | D9: HILUX | E9: EEF | F9: 3-523 | G9: 45523 | H9: =IF(G9="","",IF(J9="",TODAY()-G9,J9-G9)) -> 1 | I9: ROLAMENTO REY CARDAN | J9: 45524 | K9: CONTRATAÇÃO
A10: 7818 | B10: EEF9171 | C10: 2014 | D10: SPACEFOX | E10: APMBB | F10: BA-040 | G10: 45041 | H10: =IF(G10="","",IF(J10="",TODAY()-G10,J10-G10)) -> 615 | I10: TROCA DE BATERIA | J10: 45656 | K10: REPARADO - LIBERADA
A11: 9737 | B11: EEF9384 | C11: 2014 | D11: HILUX | E11: CMM/SAF | F11: ***** | G11: 45566 | H11: =IF(G11="","",IF(J11="",TODAY()-G11,J11-G11)) -> 1 | I11: TROCA DOS CILINDROS DO FREIO TRASEIRO (CARTÃO DE ADIANTAMENTO) | J11: 45567 | K11: SINALIZADOR
A12: 10235 | B12: ETE-0383 | C12: 2018 | D12: TRAILBLAZER | E12: CPM | F12: 3-529 | G12: 45492 | H12: =IF(G12="","",IF(J12="",TODAY()-G12,J12-G12)) -> 0 | I12: TROCA LÂMPADA FAROL DE POSIÇÃO | J12: 45492 | K12: REPARADO - LIBERADA
A13: 11132 | B13: FWI1421 | C13: 2015 | D13: SPIN | E13: ESSGT | F13: ESSGT 0-20 | G13: 45562 | H13: =IF(G13="","",IF(J13="",TODAY()-G13,J13-G13)) -> 3 | I13: TROCA DE BATERIA | J13: 45565 | K13: REPARADO - LIBERADA
A14: 11449 | B14: DJM8683 | C14: 2014 | D14: CRUZE | E14: DEC | F14: 15-109 | G14: 45338 | H14: =IF(G14="","",IF(J14="",TODAY()-G14,J14-G14)) -> 123 | I14: QUEIMANDO ÓLEO | J14: 45461 | K14: REPARADO - LIBERADA
A15: 11744 | B15: FCF9549 | C15: 2017 | D15: PALIO WEEKEND | E15: CIAP | F15: 22-1308 | G15: 45356 | H15: =IF(G15="","",IF(J15="",TODAY()-G15,J15-G15)) -> 105 | I15: BATERIA NÃO SEGURA CARGA | J15: 45461 | K15: GRAFISMO
A16: 11838 | B16: GBA9890 | C16: 2015 | D16: SPIN | E16: CMM | F16: 22-836 | G16: 45359 | H16: =IF(G16="","",IF(J16="",TODAY()-G16,J16-G16)) -> 97 | I16: MOTOR / SUSPENSÃO/ AR CONDICIONADO | J16: 45456 | K16: CONTRATAÇÃO
A17: 11877 | B17: GBA6310 | C17: 2015 | D17: SPIN | E17: APMBB | F17: BA-046 | G17: 45362 | H17: =IF(G17="","",IF(J17="",TODAY()-G17,J17-G17)) -> 102 | I17: SUSPENSÃO TRAS. E DIANT/ INJEÇÃO ELETR./ PNEUS/ LANTERNAS | J17: 45464 | K17: CONTRATAÇÃO
A18: 11892 | B18: GBQ4440 | C18: 2015 | D18: SPIN | E18: CMM | F18: 22-464 | G18: 45363 | H18: =IF(G18="","",IF(J18="",TODAY()-G18,J18-G18)) -> 106 | I18: AR CONDICIONADO/ ARREFECIMENTO/BARULHO MOTOR | J18: 45469 | K18: CONTRATAÇÃO
A19: 11898 | B19: FVU3593 | C19: 2015 | D19: SPIN | E19: APMTJ | F19: 17-13 | G19: 45363 | H19: =IF(G19="","",IF(J19="",TODAY()-G19,J19-G19)) -> 101 | I19: VAZAMENTO ÓLEO MOTOR/ SINALIZADOR | J19: 45464 | K19: CONTRATAÇÃO
A20: 12104 | B20: CMW7395 | C20: 2011 | D20: VECTRA | E20: COORDOP PM | F20: 15-134 | G20: 45476 | H20: =IF(G20="","",IF(J20="",TODAY()-G20,J20-G20)) -> 0 | I20: TROCA DE BATERIA | J20: 45476 | K20: REPARADO - LIBERADA
... A39: 12968 | B39: FPP1023 | C39: 2019 | D39: TRAILBLAZER | E39: COPOM | F39: 3-826 | G39: 45449 | H39: =IF(G39="","",IF(J39="",TODAY()-G39,J39-G39)) -> 4 | I39: AR CONDICIONADO INOPERANE | J39: 45453 | K39: CONTRATAÇÃO
A40: 12981 | B40: GDN4E65 | C40: 2021 | D40: TRAILBLAZER | E40: PMRG | F40: 45308 | G40: 45453 | H40: =IF(G40="","",IF(J40="",TODAY()-G40,J40-G40)) -> 0 | I40: TROCA DE PASTILHA DE FREIO | J40: 45453 | K40: GRAFISMO
A41: 12982 | B41: ETZ7163 | C41: 2020 | D41: SPIN | E41: PMRG | F41: 15-20 | G41: 45450 | H41: =IF(G41="","",IF(J41="",TODAY()-G41,J41-G41)) -> 3 | I41: MOTOR DE ARRANQUE | J41: 45453 | K41: CONTRATAÇÃO
A42: 12985 | B42: BYP4277 | C42: 2018 | D42: SPIN | E42: APMBB | F42: BA-050 | G42: 45525 | H42: =IF(G42="","",IF(J42="",TODAY()-G42,J42-G42)) -> 2 | I42: REPARO NO CHICOTE DO FAROL E TROCA DE LÂMPADAS | J42: 23/08/2024 | K42: GRAFISMO
A43: 12986 | B43: DJL7764 | C43: 2011 | D43: BLAZER | E43: DSA/CG | F43: 15-92 | G43: 45450 | H43: =IF(G43="","",IF(J43="",TODAY()-G43,J43-G43)) -> 5 | I43: REPARO CHAVE DE IGNIÇÃO | J43: 45455 | K43: REPARADO - LIBERADA
A44: 12994 | B44: GAD6947 | C44: 2020 | D44: FIAT UNO WAY | E44: CIAP | F44: 45427 | G44: 45453 | H44: =IF(G44="","",IF(J44="",TODAY()-G44,J44-G44)) -> 0 | I44: PASTILHA DE FREIO | J44: 45453 | K44: REPARADO - LIBERADA
A45: 12996 | B45: CFY4296 | C45: 2014 | D45: SPACE FOX | E45: APMBB | F45: BA-023 | G45: 45453 | H45: =IF(G45="","",IF(J45="",TODAY()-G45,J45-G45)) -> 66 | I45: ARREFECIMENTO/ INJEÇÃO/ BALANCIAMENTO | J45: 45519 | K45: CONTRATAÇÃO
A46: 12997 | B46: DZF0F31 | C46: 2021 | D46: DUSTER | E46: CMIL | F46: 22-196 | G46: 45456 | H46: =IF(G46="","",IF(J46="",TODAY()-G46,J46-G46)) -> 0 | I46: REVISÃO ELETRICA | J46: 45456 | K46: REPARADO - LIBERADA
A47: 13000 | B47: GCG1620 | C47: 2015 | D47: SPIN | E47: CPC | F47: 22-835 | G47: 45454 | H47: =IF(G47="","",IF(J47="",TODAY()-G47,J47-G47)) -> 10 | I47: FALHA DE IGNIÇÃO/ TROCA DE ÓLEO | J47: 45464 | K47: REPARADO - LIBERADA
A48: 13004 | B48: FYR7284 | C48: 2015 | D48: GOL CITY | E48: CIPM | F48: 8-787 | G48: 45454 | H48: =IF(G48="","",IF(J48="",TODAY()-G48,J48-G48)) -> 0 | I48: PARABRISA TRINCADO | J48: 45454 | K48: CONTRATAÇÃO
A49: 13005 | B49: FQW6145 | C49: 2015 | D49: CRUZE | E49: CIPM | F49: 8-851 | G49: 45454 | H49: =IF(G49="","",IF(J49="",TODAY()-G49,J49-G49)) -> 2 | I49: MOTOR/ AR COND./ SUSPENSÃO | J49: 45456 | K49: CONTRATAÇÃO
A50: 13006 | B50: GAS3139 | C50: 2016 | D50: SPIN | E50: 3ºEM/PM | F50: 15-17 | G50: 45455 | H50: =IF(G50="","",IF(J50="",TODAY()-G50,J50-G50)) -> 40 | I50: REVISÃO GERAL | J50: 45495 | K50: REPARADO - LIBERADA
A51: 13009 | B51: FYL5201 | C51: 2015 | D51: MONTANA | E51: CIPM | F51: 8-876 | G51: 45454 | H51: =IF(G51="","",IF(J51="",TODAY()-G51,J51-G51)) -> 0 | I51: TROCA DE LAMPADAS | J51: 45454 | K51: CONTRATAÇÃO
A52: 13011 | B52: FNR2582 | C52: 2015 | D52: TRAILBLAZER | E52: CMM | F52: 3-210 | G52: 45454 | H52: =IF(G52="","",IF(J52="",TODAY()-G52,J52-G52)) -> 0 | I52: TROCA DE LAMPADA/ ANÁLISE COM SCANNER | J52: 45454 | K52: BORRACHARIA
A53: 13017 | B53: EEF8697 | C53: 2014 | D53: S10 | E53: DSA/CG | F53: 3-276 | G53: 45455 | H53: =IF(G53="","",IF(J53="",TODAY()-G53,J53-G53)) -> 1 | I53: REVISÃO GERAL | J53: 45456 | K53: BORRACHARIA
A54: 13033 | B54: EEF8703 | C54: 2015 | D54: COROLLA | E54: GAB COM GERAL | F54: 1-120 | G54: 45456 | H54: =IF(G54="","",IF(J54="",TODAY()-G54,J54-G54)) -> 0 | I54: PARABARRO | J54: 45456 | K54: CONTRATAÇÃO
A55: 13035 | B55: REV4E91 | C55: 2022 | D55: S10 | E55: DTIC | F55: 15-49 | G55: 45723 | H55: =IF(G55="","",IF(J55="",TODAY()-G55,J55-G55)) -> 3 | I55: AJUSTE NO ESTRIBO, TROCA DE ÓLEO | J55: 45726 | K55: REPARADO - LIBERADA
A56: 13047 | B56: CMW7420 | C56: 2011 | D56: VECTRA | E56: COPOM | F56: 15-161 | G56: 45457 | H56: =IF(G56="","",IF(J56="",TODAY()-G56,J56-G56)) -> 17 | I56: TROCA DE PASTILHA DE FREIO/ FAROL QUEBRADO | J56: 45474 | K56: REPARADO - LIBERADA
... A65: 13073 | B65: EZU7632 | C65: 2019 | D65: HILUX SW4 | E65: SSP | F65: 15-33 | G65: 45461 | H65: =IF(G65="","",IF(J65="",TODAY()-G65,J65-G65)) -> 0 | I65: LAMPADA FAROL | J65: 45461 | K65: REPARADO - LIBERADA
A66: 13074 | B66: FDB8J91 | C66: 2022 | D66: TRAILBLAZER | E66: PMRG | F66: 45368 | G66: 45461 | H66: =IF(G66="","",IF(J66="",TODAY()-G66,J66-G66)) -> 0 | I66: TROCA DE BATERIA | J66: 45461 | K66: REPARADO - LIBERADA
...

Sheet ESTATISTICA
A1: QTD EM EXECUÇÃO | B1: PRAZO EM EXECUÇÃO (DIAS) | C1: QTD FINALIZADOS | D1: PRAZO FINALIZADOS (DIAS)
A2: =COUNT('VTR AGUARDANDO VISTORIA'!A:A)-A5 -> 482 | B2: =(SUMIF('VTR AGUARDANDO VISTORIA'!K:K,"<>CONTRATAÇÃO - DESCARGA",'VTR AGUARDANDO VISTORIA'!H:H))/A2 -> #VALUE! | C2: =COUNT('VTR PRONTA'!H:H) -> 1606 | D2: =(SUMIF('VTR PRONTA'!K:K,"<>CONTRATAÇÃO - DESCARGA",'VTR PRONTA'!H:H))/C2 -> 9.6899128
A4: QTD DESCARGA EXECUÇÃO | B4: PRAZO EXECUÇÃO DESCARGA (DIAS) | C4: QTD DESCARGA FINALIZADO | D4: PRAZO FINALIZADOS DESCARGA (DIAS)
A5: =COUNTIF('VTR AGUARDANDO VISTORIA'!K:K,"CONTRATAÇÃO - DESCARGA") -> 0 | B5: =IF(A5=0,0,(SUMIF('VTR AGUARDANDO VISTORIA'!K:K,"=CONTRATAÇÃO - DESCARGA",'VTR AGUARDANDO VISTORIA'!H:H))/A5) -> 0 | C5: =COUNT('VTR DESCARGA'!H:H) -> 46 | D5: =(SUMIF('VTR DESCARGA'!K:K,"=CONTRATAÇÃO - DESCARGA",'VTR DESCARGA'!H:H))/C5 -> 135.13043
